Workbook

Sheet BoardingByRoute_All
D1: BOARDINGS BY SUB-MODE
E2: OBS | G2: ABM | I2: DIFF | K2: Sub-mode Constant (DaySim) | N2: NOTE:
C3: Mode | D3: Transit sub-mode | E3: Count | F3: Percentage | G3: Count | H3: Percentage | I3: Count | J3: Percentage | K3: Utils | L3: Mins | N3: diff in by sub-mode in TrnStat.asc and this table is because of Rte 18 Airport Exp. There are two servies, one is Exp and one local. TrnStat.asc considers both as local. | AX3: Path Impedance
C4: 1 | D4: Local Bus | E4: =SUMIF($A$15:$A$48,1,E$15:E$49)+SUMIF($A$15:$A$48,2,E$15:E$49) -> 28406.591 | F4: =E4/E$8 -> 0.82549048 | G4: =SUMIF($A$15:$A$48,1,G$15:G$48)+SUMIF($A$15:$A$48,2,G$15:G$48) -> 30879 | H4: =PrilimTable!F57 -> 0.95765807 | I4: =G4-E4 -> 2472.4091 | J4: =IFERROR(I4/E4,0) -> 0.087036459 | K4: =PrilimTable!G57 -> -0.1 | L4: =PrilimTable!H57 -> -3.3333333 | AX4: PathImpedance_TransitLocalBusPathConstant = 0.05
C5: 6,7 | D5: Express Bus | E5: =SUMIF($A$15:$A$48,6,E$15:E$49)+SUMIF($A$15:$A$48,7,E$15:E$49) -> 1004.4545 | F5: =E5/E$8 -> 0.029189271 | G5: =SUMIF($A$15:$A$48,6,G$15:G$48)+SUMIF($A$15:$A$48,7,G$15:G$48) -> 538 | H5: =PrilimTable!F58 -> 0.0050593869 | I5: =G5-E5 -> -466.45455 | J5: =IFERROR(I5/E5,0) -> -0.46438592 | K5: =PrilimTable!G58 -> 0.45 | L5: =PrilimTable!H58 -> 15 | AX5: PathImpedance_TransitPremiumBusPathConstant = 0.12
C6: 8 | D6: BRT | E6: =SUMIF($A$15:$A$48,8,E$15:E$49) -> 4470.8636 | F6: =E6/E$8 -> 0.1299225 | G6: =SUMIF($A$15:$A$48,8,G$15:G$48) -> 4313 | H6: =PrilimTable!F59 -> 0.0039771651 | I6: =G6-E6 -> -157.86364 | J6: =IFERROR(I6/E6,0) -> -0.035309428 | K6: =PrilimTable!G59 -> -0.1 | L6: =PrilimTable!H59 -> -3.3333333 | AX6: PathImpedance_TransitLightRailPathConstant = 0.0
C7: 11,12 | D7: Commuter Rail | E7: =SUMIF($A$15:$A$48,11,E$15:E$49)+SUMIF($A$15:$A$48,12,E$15:E$49) -> 529.86364 | F7: =E7/E$8 -> 0.015397743 | G7: =SUMIF($A$15:$A$48,11,G$15:G$48)+SUMIF($A$15:$A$48,12,G$15:G$48) -> 1231 | H7: =PrilimTable!F60 -> 0.033305376 | I7: =G7-E7 -> 701.13636 | J7: =IFERROR(I7/E7,0) -> 1.3232393 | K7: =PrilimTable!G60 -> 1.3 | L7: =PrilimTable!H60 -> 43.333333 | AX7: PathImpedance_TransitCommuterRailPathConstant = 1.15
D8: Total | E8: =SUM(E4:E7) -> 34411.773 | F8: =E8/E$8 -> 1 | G8: =SUM(G4:G7) -> 36961 | H8: 1 | I8: =G8-E8 -> 2549.2273 | J8: =I8/E8 -> 0.074080092 | AX8: PathImpedance_TransitFerryPathConstant = 0.07
D9: Transit trips | E9: 25693 | G9: =TrnStat.asc!E18 -> 22717 | AX9: PathImpedance_TransitUsePathTypeSpecificTime = true
D10: Boarding rate | E10: =E8/E9 -> 1.3393443 | G10: =G8/G9 -> 1.6270194 | K10: Transfer Rate | L10: =PrilimTable!E63 -> 0.3437
D11: R-Squared | E11: =RSQ(G15:G48,E15:E48) -> 0.61396787 | AX11: PathImpedance_TransitPremiumBusTimeAdditiveWeight = -0.204
B12: BOARDINGS BY ROUTE | X12: BOARDINGS BY ROUTE (SORTED BY OBS BOARDINGS) | AX12: PathImpedance_TransitLightRailTimeAdditiveWeight = 0.0
E13: OBS | G13: ABM | I13: DIFF | AA13: OBS | AC13: =G13 -> ABM | AE13: DIFF | AX13: PathImpedance_TransitCommuterRailTimeAdditiveWeight = -0.273
A14: Mode | B14: Rte Id (OBS) | C14: Rte Id (ABM) | D14: Rte Name | E14: Boardings | F14: Percentage | G14: Boardings | H14: Percentage | I14: Diff | J14: % Diff | X14: Rte Id (OBS) | Y14: Rte Id (ABM) | Z14: Rte Name | AA14: Boardings | AB14: Percentage | AC14: Boardings | AD14: Percentage | AE14: Diff | AF14: % Diff | AG14: Reference | AX14: PathImpedance_TransitFerryTimeAdditiveWeight = -0.318
A15: =VLOOKUP($C15,PrilimTable!$N:$T,7,FALSE) -> 1 | B15: 3 | C15: =B15 -> 3 | D15: =VLOOKUP($C15,PrilimTable!$N:$S,2,FALSE) -> Rte 3 West End (White Bridge) IB | E15: =SUMIF(PrilimTable!$M$4:$M$82,B15,PrilimTable!$P$4:$P$82) -> 2516.9091 | F15: =E15/$E$49 -> 0.073140931 | G15: =SUMIF(PrilimTable!$N$4:$N$82,C15,PrilimTable!$R$4:$R$82) -> 8057 | H15: =G15/$G$49 -> 0.21798653 | I15: =G15-E15 -> 5540.0909 | J15: =I15/E15 -> 2.2011486 | X15: 55 | Y15: 55 | Z15: =VLOOKUP(Y15,$C$14:$D$49,2,FALSE) -> Rte 55 MURFREESBORO PIKE oB | AA15: =SUMIF(PrilimTable!$M$4:$M$82,X15,PrilimTable!$P$4:$P$82) -> 5829.3636 | AB15: =AA15/$E$49 -> 0.16940027 | AC15: =SUMIF(PrilimTable!$N$4:$N$82,Y15,PrilimTable!$R$4:$R$82) -> 4122 | AD15: =AC15/$G$49 -> 0.11152296 | AE15: =AC15-AA15 -> -1707.3636 | AF15: =AE15/AA15 -> -0.29289023 | AG15: 100
A16: =VLOOKUP($C16,PrilimTable!$N:$T,7,FALSE) -> 1 | B16: 4 | C16: =B16 -> 4 | D16: =VLOOKUP($C16,PrilimTable!$N:$S,2,FALSE) -> Rte 4 Shelby IB | E16: =SUMIF(PrilimTable!$M$4:$M$82,B16,PrilimTable!$P$4:$P$82) -> 941.04545 | F16: =E16/$E$49 -> 0.027346614 | G16: =SUMIF(PrilimTable!$N$4:$N$82,C16,PrilimTable!$R$4:$R$82) -> 299 | H16: =G16/$G$49 -> 0.008089608 | I16: =G16-E16 -> -642.04545 | J16: =I16/E16 -> -0.68226827 | X16: 56 | Y16: 56 | Z16: =VLOOKUP(Y16,$C$14:$D$49,2,FALSE) -> Rte 56 Gallatin Rd IB | AA16: =SUMIF(PrilimTable!$M$4:$M$82,X16,PrilimTable!$P$4:$P$82) -> 4470.8636 | AB16: =AA16/$E$49 -> 0.1299225 | AC16: =SUMIF(PrilimTable!$N$4:$N$82,Y16,PrilimTable!$R$4:$R$82) -> 4313 | AD16: =AC16/$G$49 -> 0.11669057 | AE16: =AC16-AA16 -> -157.86364 | AF16: =AE16/AA16 -> -0.035309428 | AG16: 200 | AX16: PathImpedance_TransitPremiumBusInVehicleTimeWeight = 0.95
A17: =VLOOKUP($C17,PrilimTable!$N:$T,7,FALSE) -> 1 | B17: 6 | C17: =B17 -> 6 | D17: =VLOOKUP($C17,PrilimTable!$N:$S,2,FALSE) -> Rte 6 Lebanon Rd OB | E17: =SUMIF(PrilimTable!$M$4:$M$82,B17,PrilimTable!$P$4:$P$82) -> 818.18182 | F17: =E17/$E$49 -> 0.023776218 | G17: =SUMIF(PrilimTable!$N$4:$N$82,C17,PrilimTable!$R$4:$R$82) -> 622 | H17: =G17/$G$49 -> 0.016828549 | I17: =G17-E17 -> -196.18182 | J17: =I17/E17 -> -0.23977778 | X17: 52 | Y17: 52 | Z17: =VLOOKUP(Y17,$C$14:$D$49,2,FALSE) -> Rte 52 NOLENSVILLE PIKE (Hick) oB | AA17: =SUMIF(PrilimTable!$M$4:$M$82,X17,PrilimTable!$P$4:$P$82) -> 3623.8636 | AB17: =AA17/$E$49 -> 0.10530883 | AC17: =SUMIF(PrilimTable!$N$4:$N$82,Y17,PrilimTable!$R$4:$R$82) -> 3228 | AD17: =AC17/$G$49 -> 0.087335299 | AE17: =AC17-AA17 -> -395.86364 | AF17: =AE17/AA17 -> -0.10923801 | AG17: 300 | AX17: PathImpedance_TransitLightRailInVehicleTimeWeight = 1.0
A18: =VLOOKUP($C18,PrilimTable!$N:$T,7,FALSE) -> 1 | B18: 7 | C18: =B18 -> 7 | D18: =VLOOKUP($C18,PrilimTable!$N:$S,2,FALSE) -> Rte 7 Hillsboro IB | E18: =SUMIF(PrilimTable!$M$4:$M$82,B18,PrilimTable!$P$4:$P$82) -> 1841.5909 | F18: =E18/$E$49 -> 0.053516305 | G18: =SUMIF(PrilimTable!$N$4:$N$82,C18,PrilimTable!$R$4:$R$82) -> 2656 | H18: =G18/$G$49 -> 0.071859528 | I18: =G18-E18 -> 814.40909 | J18: =I18/E18 -> 0.44223127 | X18: 23 | Y18: 23 | Z18: =VLOOKUP(Y18,$C$14:$D$49,2,FALSE) -> Rte 23 Dickerson Pike OB | AA18: =SUMIF(PrilimTable!$M$4:$M$82,X18,PrilimTable!$P$4:$P$82) -> 2690.5 | AB18: =AA18/$E$49 -> 0.078185452 | AC18: =SUMIF(PrilimTable!$N$4:$N$82,Y18,PrilimTable!$R$4:$R$82) -> 1650 | AD18: =AC18/$G$49 -> 0.044641649 | AE18: =AC18-AA18 -> -1040.5 | AF18: =AE18/AA18 -> -0.38673109 | AG18: 400 | AX18: PathImpedance_TransitCommuterRailInVehicleTimeWeight = 0.65
A19: =VLOOKUP($C19,PrilimTable!$N:$T,7,FALSE) -> 1 | B19: 8 | C19: =B19 -> 8 | D19: =VLOOKUP($C19,PrilimTable!$N:$S,2,FALSE) -> Rte 8 8TH AVENUE SOUTH iB | E19: =SUMIF(PrilimTable!$M$4:$M$82,B19,PrilimTable!$P$4:$P$82) -> 944.40909 | F19: =E19/$E$49 -> 0.02744436 | G19: =SUMIF(PrilimTable!$N$4:$N$82,C19,PrilimTable!$R$4:$R$82) -> 839 | H19: =G19/$G$49 -> 0.022699602 | I19: =G19-E19 -> -105.40909 | J19: =I19/E19 -> -0.1116138 | X19: 50 | Y19: 50 | Z19: =VLOOKUP(Y19,$C$14:$D$49,2,FALSE) -> Rte 50 CHARLOTTE PIKE oB | AA19: =SUMIF(PrilimTable!$M$4:$M$82,X19,PrilimTable!$P$4:$P$82) -> 2542.8636 | AB19: =AA19/$E$49 -> 0.073895165 | AC19: =SUMIF(PrilimTable!$N$4:$N$82,Y19,PrilimTable!$R$4:$R$82) -> 2777 | AD19: =AC19/$G$49 -> 0.075133249 | AE19: =AC19-AA19 -> 234.13636 | AF19: =AE19/AA19 -> 0.092075863 | AG19: 500 | AX19: PathImpedance_TransitFerryInVehicleTimeWeight = 0.80
A20: =VLOOKUP($C20,PrilimTable!$N:$T,7,FALSE) -> 1 | B20: 9 | C20: =B20 -> 9 | D20: =VLOOKUP($C20,PrilimTable!$N:$S,2,FALSE) -> Rte 9 MetroCenter OB | E20: =SUMIF(PrilimTable!$M$4:$M$82,B20,PrilimTable!$P$4:$P$82) -> 350.59091 | F20: =E20/$E$49 -> 0.01018811 | G20: =SUMIF(PrilimTable!$N$4:$N$82,C20,PrilimTable!$R$4:$R$82) -> 834 | H20: =G20/$G$49 -> 0.022564325 | I20: =G20-E20 -> 483.40909 | J20: =I20/E20 -> 1.3788409 | X20: 3 | Y20: 3 | Z20: =VLOOKUP(Y20,$C$14:$D$49,2,FALSE) -> Rte 3 West End (White Bridge) IB | AA20: =SUMIF(PrilimTable!$M$4:$M$82,X20,PrilimTable!$P$4:$P$82) -> 2516.9091 | AB20: =AA20/$E$49 -> 0.073140931 | AC20: =SUMIF(PrilimTable!$N$4:$N$82,Y20,PrilimTable!$R$4:$R$82) -> 8057 | AD20: =AC20/$G$49 -> 0.21798653 | AE20: =AC20-AA20 -> 5540.0909 | AF20: =AE20/AA20 -> 2.2011486 | AG20: 600
A21: =VLOOKUP($C21,PrilimTable!$N:$T,7,FALSE) -> 1 | B21: 14 | C21: =B21 -> 14 | D21: =VLOOKUP($C21,PrilimTable!$N:$S,2,FALSE) -> Rte 14 WHITES CREEK oB | E21: =SUMIF(PrilimTable!$M$4:$M$82,B21,PrilimTable!$P$4:$P$82) -> 334.18182 | F21: =E21/$E$49 -> 0.0097112642 | G21: =SUMIF(PrilimTable!$N$4:$N$82,C21,PrilimTable!$R$4:$R$82) -> 328 | H21: =G21/$G$49 -> 0.0088742188 | I21: =G21-E21 -> -6.1818182 | J21: =I21/E21 -> -0.018498368 | X21: 7 | Y21: 7 | Z21: =VLOOKUP(Y21,$C$14:$D$49,2,FALSE) -> Rte 7 Hillsboro IB | AA21: =SUMIF(PrilimTable!$M$4:$M$82,X21,PrilimTable!$P$4:$P$82) -> 1841.5909 | AB21: =AA21/$E$49 -> 0.053516305 | AC21: =SUMIF(PrilimTable!$N$4:$N$82,Y21,PrilimTable!$R$4:$R$82) -> 2656 | AD21: =AC21/$G$49 -> 0.071859528 | AE21: =AC21-AA21 -> 814.40909 | AF21: =AE21/AA21 -> 0.44223127 | AG21: 700
A22: =VLOOKUP($C22,PrilimTable!$N:$T,7,FALSE) -> 1 | B22: 17 | C22: =B22 -> 17 | D22: =VLOOKUP($C22,PrilimTable!$N:$S,2,FALSE) -> Rte 17 12TH AVENUE SOUTH iB | E22: =SUMIF(PrilimTable!$M$4:$M$82,B22,PrilimTable!$P$4:$P$82) -> 637.95455 | F22: =E22/$E$49 -> 0.018538846 | G22: =SUMIF(PrilimTable!$N$4:$N$82,C22,PrilimTable!$R$4:$R$82) -> 886 | H22: =G22/$G$49 -> 0.023971213 | I22: =G22-E22 -> 248.04545 | J22: =I22/E22 -> 0.38881368 | X22: 22 | Y22: 22 | Z22: =VLOOKUP(Y22,$C$14:$D$49,2,FALSE) -> Rte 22 Bordeaux (Panaroma) IB | AA22: =SUMIF(PrilimTable!$M$4:$M$82,X22,PrilimTable!$P$4:$P$82) -> 1505.4091 | AB22: =AA22/$E$49 -> 0.043746921 | AC22: =SUMIF(PrilimTable!$N$4:$N$82,Y22,PrilimTable!$R$4:$R$82) -> 1697 | AD22: =AC22/$G$49 -> 0.04591326 | AE22: =AC22-AA22 -> 191.59091 | AF22: =AE22/AA22 -> 0.12726834 | AG22: 800
A23: =VLOOKUP($C23,PrilimTable!$N:$T,7,FALSE) -> 6 | B23: 18 | C23: =B23 -> 18 | D23: =VLOOKUP($C23,PrilimTable!$N:$S,2,FALSE) -> Rte 18 Airport Exp OB | E23: =SUMIF(PrilimTable!$M$4:$M$82,B23,PrilimTable!$P$4:$P$82) -> 677.90909 | F23: =E23/$E$49 -> 0.019699918 | G23: =SUMIF(PrilimTable!$N$4:$N$82,C23,PrilimTable!$R$4:$R$82) -> 358 | H23: =G23/$G$49 -> 0.0096858851 | I23: =G23-E23 -> -319.90909 | J23: =I23/E23 -> -0.47190559 | X23: 19 | Y23: 19 | Z23: =VLOOKUP(Y23,$C$14:$D$49,2,FALSE) -> Rte 19 Herman IB | AA23: =SUMIF(PrilimTable!$M$4:$M$82,X23,PrilimTable!$P$4:$P$82) -> 955.72727 | AB23: =AA23/$E$49 -> 0.027773265 | AC23: =SUMIF(PrilimTable!$N$4:$N$82,Y23,PrilimTable!$R$4:$R$82) -> 1053 | AD23: =AC23/$G$49 -> 0.028489489 | AE23: =AC23-AA23 -> 97.272727 | AF23: =AE23/AA23 -> 0.10177875 | AG23: 900
A24: =VLOOKUP($C24,PrilimTable!$N:$T,7,FALSE) -> 1 | B24: 19 | C24: =B24 -> 19 | D24: =VLOOKUP($C24,PrilimTable!$N:$S,2,FALSE) -> Rte 19 Herman IB | E24: =SUMIF(PrilimTable!$M$4:$M$82,B24,PrilimTable!$P$4:$P$82) -> 955.72727 | F24: =E24/$E$49 -> 0.027773265 | G24: =SUMIF(PrilimTable!$N$4:$N$82,C24,PrilimTable!$R$4:$R$82) -> 1053 | H24: =G24/$G$49 -> 0.028489489 | I24: =G24-E24 -> 97.272727 | J24: =I24/E24 -> 0.10177875 | X24: 8 | Y24: 8 | Z24: =VLOOKUP(Y24,$C$14:$D$49,2,FALSE) -> Rte 8 8TH AVENUE SOUTH iB | AA24: =SUMIF(PrilimTable!$M$4:$M$82,X24,PrilimTable!$P$4:$P$82) -> 944.40909 | AB24: =AA24/$E$49 -> 0.02744436 | AC24: =SUMIF(PrilimTable!$N$4:$N$82,Y24,PrilimTable!$R$4:$R$82) -> 839 | AD24: =AC24/$G$49 -> 0.022699602 | AE24: =AC24-AA24 -> -105.40909 | AF24: =AE24/AA24 -> -0.1116138 | AG24: 1000
A25: =VLOOKUP($C25,PrilimTable!$N:$T,7,FALSE) -> 1 | B25: 22 | C25: =B25 -> 22 | D25: =VLOOKUP($C25,PrilimTable!$N:$S,2,FALSE) -> Rte 22 Bordeaux (Panaroma) IB | E25: =SUMIF(PrilimTable!$M$4:$M$82,B25,PrilimTable!$P$4:$P$82) -> 1505.4091 | F25: =E25/$E$49 -> 0.043746921 | G25: =SUMIF(PrilimTable!$N$4:$N$82,C25,PrilimTable!$R$4:$R$82) -> 1697 | H25: =G25/$G$49 -> 0.04591326 | I25: =G25-E25 -> 191.59091 | J25: =I25/E25 -> 0.12726834 | X25: 4 | Y25: 4 | Z25: =VLOOKUP(Y25,$C$14:$D$49,2,FALSE) -> Rte 4 Shelby IB | AA25: =SUMIF(PrilimTable!$M$4:$M$82,X25,PrilimTable!$P$4:$P$82) -> 941.04545 | AB25: =AA25/$E$49 -> 0.027346614 | AC25: =SUMIF(PrilimTable!$N$4:$N$82,Y25,PrilimTable!$R$4:$R$82) -> 299 | AD25: =AC25/$G$49 -> 0.008089608 | AE25: =AC25-AA25 -> -642.04545 | AF25: =AE25/AA25 -> -0.68226827 | AG25: 1100
A26: =VLOOKUP($C26,PrilimTable!$N:$T,7,FALSE) -> 1 | B26: 23 | C26: =B26 -> 23 | D26: =VLOOKUP($C26,PrilimTable!$N:$S,2,FALSE) -> Rte 23 Dickerson Pike OB | E26: =SUMIF(PrilimTable!$M$4:$M$82,B26,PrilimTable!$P$4:$P$82) -> 2690.5 | F26: =E26/$E$49 -> 0.078185452 | G26: =SUMIF(PrilimTable!$N$4:$N$82,C26,PrilimTable!$R$4:$R$82) -> 1650 | H26: =G26/$G$49 -> 0.044641649 | I26: =G26-E26 -> -1040.5 | J26: =I26/E26 -> -0.38673109 | X26: 6 | Y26: 6 | Z26: =VLOOKUP(Y26,$C$14:$D$49,2,FALSE) -> Rte 6 Lebanon Rd OB | AA26: =SUMIF(PrilimTable!$M$4:$M$82,X26,PrilimTable!$P$4:$P$82) -> 818.18182 | AB26: =AA26/$E$49 -> 0.023776218 | AC26: =SUMIF(PrilimTable!$N$4:$N$82,Y26,PrilimTable!$R$4:$R$82) -> 622 | AD26: =AC26/$G$49 -> 0.016828549 | AE26: =AC26-AA26 -> -196.18182 | AF26: =AE26/AA26 -> -0.23977778 | AG26: 1200
A27: =VLOOKUP($C27,PrilimTable!$N:$T,7,FALSE) -> 1 | B27: 28 | C27: =B27 -> 28 | D27: =VLOOKUP($C27,PrilimTable!$N:$S,2,FALSE) -> Rte 28 Meridian IB | E27: =SUMIF(PrilimTable!$M$4:$M$82,B27,PrilimTable!$P$4:$P$82) -> 275.40909 | F27: =E27/$E$49 -> 0.0080033392 | G27: =SUMIF(PrilimTable!$N$4:$N$82,C27,PrilimTable!$R$4:$R$82) -> 45 | H27: =G27/$G$49 -> 0.0012174995 | I27: =G27-E27 -> -230.40909 | J27: =I27/E27 -> -0.8366067 | X27: 29 | Y27: 29 | Z27: =VLOOKUP(Y27,$C$14:$D$49,2,FALSE) -> Rte 29 Jefferson IB | AA27: =SUMIF(PrilimTable!$M$4:$M$82,X27,PrilimTable!$P$4:$P$82) -> 691.09091 | AB27: =AA27/$E$49 -> 0.020082979 | AC27: =SUMIF(PrilimTable!$N$4:$N$82,Y27,PrilimTable!$R$4:$R$82) -> 582 | AD27: =AC27/$G$49 -> 0.015746327 | AE27: =AC27-AA27 -> -109.09091 | AF27: =AE27/AA27 -> -0.1578532 | AG27: 1300
A28: =VLOOKUP($C28,PrilimTable!$N:$T,7,FALSE) -> 1 | B28: 29 | C28: =B28 -> 29 | D28: =VLOOKUP($C28,PrilimTable!$N:$S,2,FALSE) -> Rte 29 Jefferson IB | E28: =SUMIF(PrilimTable!$M$4:$M$82,B28,PrilimTable!$P$4:$P$82) -> 691.09091 | F28: =E28/$E$49 -> 0.020082979 | G28: =SUMIF(PrilimTable!$N$4:$N$82,C28,PrilimTable!$R$4:$R$82) -> 582 | H28: =G28/$G$49 -> 0.015746327 | I28: =G28-E28 -> -109.09091 | J28: =I28/E28 -> -0.1578532 | X28: 18 | Y28: 18 | Z28: =VLOOKUP(Y28,$C$14:$D$49,2,FALSE) -> Rte 18 Airport Exp OB | AA28: =SUMIF(PrilimTable!$M$4:$M$82,X28,PrilimTable!$P$4:$P$82) -> 677.90909 | AB28: =AA28/$E$49 -> 0.019699918 | AC28: =SUMIF(PrilimTable!$N$4:$N$82,Y28,PrilimTable!$R$4:$R$82) -> 358 | AD28: =AC28/$G$49 -> 0.0096858851 | AE28: =AC28-AA28 -> -319.90909 | AF28: =AE28/AA28 -> -0.47190559 | AG28: 1400
A29: =VLOOKUP($C29,PrilimTable!$N:$T,7,FALSE) -> 1 | B29: 34 | C29: =B29 -> 34 | D29: =VLOOKUP($C29,PrilimTable!$N:$S,2,FALSE) -> Rte 34 Opry Mills IB | E29: =SUMIF(PrilimTable!$M$4:$M$82,B29,PrilimTable!$P$4:$P$82) -> 365.81818 | F29: =E29/$E$49 -> 0.010630611 | G29: =SUMIF(PrilimTable!$N$4:$N$82,C29,PrilimTable!$R$4:$R$82) -> 44 | H29: =G29/$G$49 -> 0.001190444 | I29: =G29-E29 -> -321.81818 | J29: =I29/E29 -> -0.87972167 | X29: 17 | Y29: 17 | Z29: =VLOOKUP(Y29,$C$14:$D$49,2,FALSE) -> Rte 17 12TH AVENUE SOUTH iB | AA29: =SUMIF(PrilimTable!$M$4:$M$82,X29,PrilimTable!$P$4:$P$82) -> 637.95455 | AB29: =AA29/$E$49 -> 0.018538846 | AC29: =SUMIF(PrilimTable!$N$4:$N$82,Y29,PrilimTable!$R$4:$R$82) -> 886 | AD29: =AC29/$G$49 -> 0.023971213 | AE29: =AC29-AA29 -> 248.04545 | AF29: =AE29/AA29 -> 0.38881368 | AG29: 1500
A30: =VLOOKUP($C30,PrilimTable!$N:$T,7,FALSE) -> 1 | B30: 41 | C30: =B30 -> 41 | D30: =VLOOKUP($C30,PrilimTable!$N:$S,2,FALSE) -> Rte 41 Golden Valley OB PM | E30: =SUMIF(PrilimTable!$M$4:$M$82,B30,PrilimTable!$P$4:$P$82) -> 61.909091 | F30: =E30/$E$49 -> 0.0017990672 | G30: =SUMIF(PrilimTable!$N$4:$N$82,C30,PrilimTable!$R$4:$R$82) -> 27 | H30: =G30/$G$49 -> 0.00073049972 | I30: =G30-E30 -> -34.909091 | J30: =I30/E30 -> -0.56387665 | X30: 42 | Y30: 42 | Z30: =VLOOKUP(Y30,$C$14:$D$49,2,FALSE) -> Rte 42 St. Cecilia/Cumberland IB | AA30: =SUMIF(PrilimTable!$M$4:$M$82,X30,PrilimTable!$P$4:$P$82) -> 402.68182 | AB30: =AA30/$E$49 -> 0.011701862 | AC30: =SUMIF(PrilimTable!$N$4:$N$82,Y30,PrilimTable!$R$4:$R$82) -> 716 | AD30: =AC30/$G$49 -> 0.01937177 | AE30: =AC30-AA30 -> 313.31818 | AF30: =AE30/AA30 -> 0.77807879 | AG30: 1600
A31: =VLOOKUP($C31,PrilimTable!$N:$T,7,FALSE) -> 1 | B31: 42 | C31: =B31 -> 42 | D31: =VLOOKUP($C31,PrilimTable!$N:$S,2,FALSE) -> Rte 42 St. Cecilia/Cumberland IB | E31: =SUMIF(PrilimTable!$M$4:$M$82,B31,PrilimTable!$P$4:$P$82) -> 402.68182 | F31: =E31/$E$49 -> 0.011701862 | G31: =SUMIF(PrilimTable!$N$4:$N$82,C31,PrilimTable!$R$4:$R$82) -> 716 | H31: =G31/$G$49 -> 0.01937177 | I31: =G31-E31 -> 313.31818 | J31: =I31/E31 -> 0.77807879 | X31: 90 | Y31: 90 | Z31: =VLOOKUP(Y31,$C$14:$D$49,2,FALSE) -> Rte 90 Music City Star oB | AA31: =SUMIF(PrilimTable!$M$4:$M$82,X31,PrilimTable!$P$4:$P$82) -> 399.31818 | AB31: =AA31/$E$49 -> 0.011604115 | AC31: =SUMIF(PrilimTable!$N$4:$N$82,Y31,PrilimTable!$R$4:$R$82) -> 40 | AD31: =AC31/$G$49 -> 0.0010822218 | AE31: =AC31-AA31 -> -359.31818 | AF31: =AE31/AA31 -> -0.89982925 | AG31: 1700
... A48: =VLOOKUP($C48,PrilimTable!$N:$T,7,FALSE) -> 6 | B48: 95 | C48: =B48 -> 95 | D48: =VLOOKUP($C48,PrilimTable!$N:$S,2,FALSE) -> Rte 95 Spring Hill Exp OB | E48: =SUMIF(PrilimTable!$M$4:$M$82,B48,PrilimTable!$P$4:$P$82) -> 51.636364 | F48: =E48/$E$49 -> 0.0015005436 | G48: =SUMIF(PrilimTable!$N$4:$N$82,C48,PrilimTable!$R$4:$R$82) -> 11 | H48: =G48/$G$49 -> 0.000297611 | I48: =G48-E48 -> -40.636364 | J48: =I48/E48 -> -0.78697183 | X48: 64 | Y48: 64 | Z48: =VLOOKUP(Y48,$C$14:$D$49,2,FALSE) -> Rte 64 STAR DOWNTOWN SHUTTLE | AA48: =SUMIF(PrilimTable!$M$4:$M$82,X48,PrilimTable!$P$4:$P$82) -> 9.1818182 | AB48: =AA48/$E$49 -> 0.000266822 | AC48: =SUMIF(PrilimTable!$N$4:$N$82,Y48,PrilimTable!$R$4:$R$82) -> 547 | AD48: =AC48/$G$49 -> 0.014799383 | AE48: =AC48-AA48 -> 537.81818 | AF48: =AE48/AA48 -> 58.574257 | AG48: 3400
D49: TOTAL | E49: =SUM(E15:E48) -> 34411.773 | F49: =SUM(F15:F48) -> 1 | G49: =SUM(G15:G48) -> 36961 | H49: =SUM(H15:H48) -> 1 | I49: =G49-E49 -> 2549.2273 | J49: =I49/E49 -> 0.074080092 | AA49: =SUM(AA15:AA48) -> 34411.773 | AB49: 0.998 | AC49: =SUM(AC15:AC48) -> 36961 | AD49: 1 | AE49: =AC49-AA49 -> 2549.2273 | AF49: =AE49/AA49 -> 0.074080092

Sheet PrilimTable
P2: OBS | R2: ABM_12132015
B3: ROUTE_STATION_NUM | C3: Boardings | M3: Rte Id (OBS) | N3: Rte Id (ABM) | O3: Rte Name | P3: Boardings | Q3: Percentage | R3: Boardings | S3: Percentage | T3: Mode
B4: 3 | C4: =VLOOKUP($B4,Aggregated_Transit_Final_V2!$B:$H,7,FALSE) -> 2516.9091 | M4: 3 | N4: 3 | O4: =VLOOKUP($N4,ABM_RteName!$A:$D,3,FALSE) -> Rte 3 West End (White Bridge) IB | P4: =VLOOKUP(M4,$B:$C,2,FALSE) -> 2516.9091 | Q4: =P4/$P$38 -> 0.073140931 | R4: =SUMIF(BoardingByRoute_ABM!$B:$B,N4,BoardingByRoute_ABM!$N:$N) -> 8057 | S4: =R4/R$38 -> 0.21798653 | T4: =VLOOKUP($N4,ABM_RteName!$A:$E,5,FALSE) -> 1
B5: 4 | C5: =VLOOKUP($B5,Aggregated_Transit_Final_V2!$B:$H,7,FALSE) -> 941.04545 | M5: 4 | N5: 4 | O5: =VLOOKUP($N5,ABM_RteName!$A:$D,3,FALSE) -> Rte 4 Shelby IB | P5: =VLOOKUP(M5,$B:$C,2,FALSE) -> 941.04545 | Q5: =P5/$P$38 -> 0.027346614 | R5: =SUMIF(BoardingByRoute_ABM!$B:$B,N5,BoardingByRoute_ABM!$N:$N) -> 299 | S5: =R5/R$38 -> 0.008089608 | T5: =VLOOKUP($N5,ABM_RteName!$A:$E,5,FALSE) -> 1
B6: 6 | C6: =VLOOKUP($B6,Aggregated_Transit_Final_V2!$B:$H,7,FALSE) -> 818.18182 | M6: 6 | N6: 6 | O6: =VLOOKUP($N6,ABM_RteName!$A:$D,3,FALSE) -> Rte 6 Lebanon Rd OB | P6: =VLOOKUP(M6,$B:$C,2,FALSE) -> 818.18182 | Q6: =P6/$P$38 -> 0.023776218 | R6: =SUMIF(BoardingByRoute_ABM!$B:$B,N6,BoardingByRoute_ABM!$N:$N) -> 622 | S6: =R6/R$38 -> 0.016828549 | T6: =VLOOKUP($N6,ABM_RteName!$A:$E,5,FALSE) -> 1
B7: 7 | C7: =VLOOKUP($B7,Aggregated_Transit_Final_V2!$B:$H,7,FALSE) -> 1841.5909 | M7: 7 | N7: 7 | O7: =VLOOKUP($N7,ABM_RteName!$A:$D,3,FALSE) -> Rte 7 Hillsboro IB | P7: =VLOOKUP(M7,$B:$C,2,FALSE) -> 1841.5909 | Q7: =P7/$P$38 -> 0.053516305 | R7: =SUMIF(BoardingByRoute_ABM!$B:$B,N7,BoardingByRoute_ABM!$N:$N) -> 2656 | S7: =R7/R$38 -> 0.071859528 | T7: =VLOOKUP($N7,ABM_RteName!$A:$E,5,FALSE) -> 1
B8: 8 | C8: =VLOOKUP($B8,Aggregated_Transit_Final_V2!$B:$H,7,FALSE) -> 944.40909 | M8: 8 | N8: 8 | O8: =VLOOKUP($N8,ABM_RteName!$A:$D,3,FALSE) -> Rte 8 8TH AVENUE SOUTH iB | P8: =VLOOKUP(M8,$B:$C,2,FALSE) -> 944.40909 | Q8: =P8/$P$38 -> 0.02744436 | R8: =SUMIF(BoardingByRoute_ABM!$B:$B,N8,BoardingByRoute_ABM!$N:$N) -> 839 | S8: =R8/R$38 -> 0.022699602 | T8: =VLOOKUP($N8,ABM_RteName!$A:$E,5,FALSE) -> 1
B9: 9 | C9: =VLOOKUP($B9,Aggregated_Transit_Final_V2!$B:$H,7,FALSE) -> 350.59091 | M9: 9 | N9: 9 | O9: =VLOOKUP($N9,ABM_RteName!$A:$D,3,FALSE) -> Rte 9 MetroCenter OB | P9: =VLOOKUP(M9,$B:$C,2,FALSE) -> 350.59091 | Q9: =P9/$P$38 -> 0.01018811 | R9: =SUMIF(BoardingByRoute_ABM!$B:$B,N9,BoardingByRoute_ABM!$N:$N) -> 834 | S9: =R9/R$38 -> 0.022564325 | T9: =VLOOKUP($N9,ABM_RteName!$A:$E,5,FALSE) -> 1
B10: 14 | C10: =VLOOKUP($B10,Aggregated_Transit_Final_V2!$B:$H,7,FALSE) -> 334.18182 | M10: 14 | N10: 14 | O10: =VLOOKUP($N10,ABM_RteName!$A:$D,3,FALSE) -> Rte 14 WHITES CREEK oB | P10: =VLOOKUP(M10,$B:$C,2,FALSE) -> 334.18182 | Q10: =P10/$P$38 -> 0.0097112642 | R10: =SUMIF(BoardingByRoute_ABM!$B:$B,N10,BoardingByRoute_ABM!$N:$N) -> 328 | S10: =R10/R$38 -> 0.0088742188 | T10: =VLOOKUP($N10,ABM_RteName!$A:$E,5,FALSE) -> 1
B11: 17 | C11: =VLOOKUP($B11,Aggregated_Transit_Final_V2!$B:$H,7,FALSE) -> 637.95455 | M11: 17 | N11: 17 | O11: =VLOOKUP($N11,ABM_RteName!$A:$D,3,FALSE) -> Rte 17 12TH AVENUE SOUTH iB | P11: =VLOOKUP(M11,$B:$C,2,FALSE) -> 637.95455 | Q11: =P11/$P$38 -> 0.018538846 | R11: =SUMIF(BoardingByRoute_ABM!$B:$B,N11,BoardingByRoute_ABM!$N:$N) -> 886 | S11: =R11/R$38 -> 0.023971213 | T11: =VLOOKUP($N11,ABM_RteName!$A:$E,5,FALSE) -> 1
B12: 18 | C12: =VLOOKUP($B12,Aggregated_Transit_Final_V2!$B:$H,7,FALSE) -> 677.90909 | M12: 18 | N12: 18 | O12: =VLOOKUP($N12,ABM_RteName!$A:$D,3,FALSE) -> Rte 18 Airport Exp OB | P12: =VLOOKUP(M12,$B:$C,2,FALSE) -> 677.90909 | Q12: =P12/$P$38 -> 0.019699918 | R12: =SUMIF(BoardingByRoute_ABM!$B:$B,N12,BoardingByRoute_ABM!$N:$N) -> 358 | S12: =R12/R$38 -> 0.0096858851 | T12: =VLOOKUP($N12,ABM_RteName!$A:$E,5,FALSE) -> 6
B13: 19 | C13: =VLOOKUP($B13,Aggregated_Transit_Final_V2!$B:$H,7,FALSE) -> 955.72727 | M13: 19 | N13: 19 | O13: =VLOOKUP($N13,ABM_RteName!$A:$D,3,FALSE) -> Rte 19 Herman IB | P13: =VLOOKUP(M13,$B:$C,2,FALSE) -> 955.72727 | Q13: =P13/$P$38 -> 0.027773265 | R13: =SUMIF(BoardingByRoute_ABM!$B:$B,N13,BoardingByRoute_ABM!$N:$N) -> 1053 | S13: =R13/R$38 -> 0.028489489 | T13: =VLOOKUP($N13,ABM_RteName!$A:$E,5,FALSE) -> 1
B14: 22 | C14: =VLOOKUP($B14,Aggregated_Transit_Final_V2!$B:$H,7,FALSE) -> 1505.4091 | M14: 22 | N14: 22 | O14: =VLOOKUP($N14,ABM_RteName!$A:$D,3,FALSE) -> Rte 22 Bordeaux (Panaroma) IB | P14: =VLOOKUP(M14,$B:$C,2,FALSE) -> 1505.4091 | Q14: =P14/$P$38 -> 0.043746921 | R14: =SUMIF(BoardingByRoute_ABM!$B:$B,N14,BoardingByRoute_ABM!$N:$N) -> 1697 | S14: =R14/R$38 -> 0.04591326 | T14: =VLOOKUP($N14,ABM_RteName!$A:$E,5,FALSE) -> 1
B15: 23 | C15: =VLOOKUP($B15,Aggregated_Transit_Final_V2!$B:$H,7,FALSE) -> 2690.5 | M15: 23 | N15: 23 | O15: =VLOOKUP($N15,ABM_RteName!$A:$D,3,FALSE) -> Rte 23 Dickerson Pike OB | P15: =VLOOKUP(M15,$B:$C,2,FALSE) -> 2690.5 | Q15: =P15/$P$38 -> 0.078185452 | R15: =SUMIF(BoardingByRoute_ABM!$B:$B,N15,BoardingByRoute_ABM!$N:$N) -> 1650 | S15: =R15/R$38 -> 0.044641649 | T15: =VLOOKUP($N15,ABM_RteName!$A:$E,5,FALSE) -> 1
... B37: 95 | C37: =VLOOKUP($B37,Aggregated_Transit_Final_V2!$B:$H,7,FALSE) -> 51.636364 | M37: 95 | N37: 95 | O37: =VLOOKUP($N37,ABM_RteName!$A:$D,3,FALSE) -> Rte 95 Spring Hill Exp OB | P37: =VLOOKUP(M37,$B:$C,2,FALSE) -> 51.636364 | Q37: =P37/$P$38 -> 0.0015005436 | R37: =SUMIF(BoardingByRoute_ABM!$B:$B,N37,BoardingByRoute_ABM!$N:$N) -> 11 | S37: =R37/R$38 -> 0.000297611 | T37: =VLOOKUP($N37,ABM_RteName!$A:$E,5,FALSE) -> 6
M38: TOTAL | P38: =SUM(P4:P37) -> 34411.773 | Q38: =SUM(Q4:Q37) -> 1 | R38: =SUM(R4:R37) -> 36961 | S38: =SUM(S4:S37) -> 1
O44: Following stations are replaced with '301'
O45: DON | P45: 301
O46: HER | P46: 301
O47: JUL | P47: 301
O48: LEB | P48: 301
O49: MAR | P49: 301
O50: RIV | P50: 301
O51: 18X | P51: 18
A54: Boardings by transit sub-mode
C55: OBS | E55: ABM | G55: Sub-mode Constant (DaySim)
B56: Transit sub-mode | C56: Count | D56: Percentage | E56: Count | F56: Percentage | G56: Utils | H56: Mins
B57: Local Bus | C57: =25297-BoardingByRoute_All!E48 -> 25245.364 | D57: =C57/$C$61 -> 0.80599462 | E57: =IF(ISNUMBER(TrnStat.asc!J26),TrnStat.asc!J26,CONCATENATE(LEFT(TrnStat.asc!J26,2),RIGHT(TrnStat.asc!J26,3))) -> 35396 | F57: =E57/E$61 -> 0.95765807 | G57: -0.1 | H57: =G57/0.03 -> -3.3333333
B58: Express Bus | C58: 2122 | D58: =C58/$C$61 -> 0.067747909 | E58: =IF(ISNUMBER(TrnStat.asc!K27),TrnStat.asc!K27,CONCATENATE(LEFT(TrnStat.asc!K27,2),RIGHT(TrnStat.asc!K27,3)))+IF(ISNUMBER(TrnStat.asc!K28),TrnStat.asc!K28,CONCATENATE(LEFT(TrnStat.asc!K28,2),RIGHT(TrnStat.asc!K28,3))) -> 187 | F58: =E58/E$61 -> 0.0050593869 | G58: 0.45 | H58: =G58/0.03 -> 15
B59: BRT | C59: 2660 | D59: =C59/$C$61 -> 0.084924334 | E59: =IF(ISNUMBER(TrnStat.asc!K29),TrnStat.asc!K29,CONCATENATE(LEFT(TrnStat.asc!K29,2),RIGHT(TrnStat.asc!K29,3))) -> 147 | F59: =E59/E$61 -> 0.0039771651 | G59: -0.1 | H59: =G59/0.03 -> -3.3333333
B60: Commuter Rail | C60: =1243+BoardingByRoute_All!E48 -> 1294.6364 | D60: =C60/$C$61 -> 0.041333132 | E60: =IF(ISNUMBER(TrnStat.asc!J30),TrnStat.asc!J30,CONCATENATE(LEFT(TrnStat.asc!J30,2),RIGHT(TrnStat.asc!J30,3)))+IF(ISNUMBER(TrnStat.asc!J31),TrnStat.asc!J31,CONCATENATE(LEFT(TrnStat.asc!J31,2),RIGHT(TrnStat.asc!J31,3))) -> 1231 | F60: =E60/E$61 -> 0.033305376 | G60: 1.3 | H60: =G60/0.03 -> 43.333333
B61: Total | C61: 31322 | D61: =C61/$C$61 -> 1 | E61: =SUM(E57:E60) -> 36961 | F61: 1
B63: Transfer Rate | C63: 0.596 | E63: =-(TrnStat.asc!D46) -> 0.3437

Sheet Aggregated_Transit_Final_V2
A1: RouteNumChar | B1: RouteNumNum | C1: RouteObs | D1: ON | E1: ObsName | F1: ObsOn | G1: ObsOff | H1: boarding
A2: 3 | B2: 3 | H2: =IFERROR(VLOOKUP(B2,Obs_Ridership!$A:$G,7,FALSE),"") -> 2516.9091
A3: 4 | B3: 4 | H3: =IFERROR(VLOOKUP(B3,Obs_Ridership!$A:$G,7,FALSE),"") -> 941.04545
A4: 6 | B4: 6 | H4: =IFERROR(VLOOKUP(B4,Obs_Ridership!$A:$G,7,FALSE),"") -> 818.18182
A5: 7 | B5: 7 | H5: =IFERROR(VLOOKUP(B5,Obs_Ridership!$A:$G,7,FALSE),"") -> 1841.5909
A6: 8 | B6: 8 | H6: =IFERROR(VLOOKUP(B6,Obs_Ridership!$A:$G,7,FALSE),"") -> 944.40909
A7: 9 | B7: 9 | H7: =IFERROR(VLOOKUP(B7,Obs_Ridership!$A:$G,7,FALSE),"") -> 350.59091
A8: 14 | B8: 14 | H8: =IFERROR(VLOOKUP(B8,Obs_Ridership!$A:$G,7,FALSE),"") -> 334.18182
A9: 17 | B9: 17 | H9: =IFERROR(VLOOKUP(B9,Obs_Ridership!$A:$G,7,FALSE),"") -> 637.95455
A10: 18 | B10: 18 | H10: =IFERROR(VLOOKUP(B10,Obs_Ridership!$A:$G,7,FALSE),"") -> 677.90909
A11: 19 | B11: 19 | H11: =IFERROR(VLOOKUP(B11,Obs_Ridership!$A:$G,7,FALSE),"") -> 955.72727
A12: 22 | B12: 22 | H12: =IFERROR(VLOOKUP(B12,Obs_Ridership!$A:$G,7,FALSE),"") -> 1505.4091
A13: 23 | B13: 23 | H13: =IFERROR(VLOOKUP(B13,Obs_Ridership!$A:$G,7,FALSE),"") -> 2690.5
... A29: 84 | B29: 84 | H29: =IFERROR(VLOOKUP(B29,Obs_Ridership!$A:$G,7,FALSE),"") -> 127.5
A30: 86 | B30: 86 | H30: =IFERROR(VLOOKUP(B30,Obs_Ridership!$A:$G,7,FALSE),"") -> 47.090909 | I30: "RouteNumNum" isn't correct, used "RouteNumChar"
A31: 87 | B31: 87 | H31: =IFERROR(VLOOKUP(B31,Obs_Ridership!$A:$G,7,FALSE),"") -> 77.318182
A32: 89 | B32: 89 | H32: =IFERROR(VLOOKUP(B32,Obs_Ridership!$A:$G,7,FALSE),"") -> 23
A33: 90 | B33: 90 | H33: =IFERROR(VLOOKUP(B33,Obs_Ridership!$A:$G,7,FALSE),"") -> 399.31818
A34: 93 | B34: 93 | H34: =IFERROR(VLOOKUP(B34,Obs_Ridership!$A:$G,7,FALSE),"") -> 121.36364
A35: 95 | B35: 95 | H35: =IFERROR(VLOOKUP(B35,Obs_Ridership!$A:$G,7,FALSE),"") -> 51.636364

Sheet TrnStat.asc
B2: Created | C2: On: | D2: Fri, | E2: Dec | F2: 27 | G2: 2024 | H2: (08:59:31)
B3: Nashville | C3: Transit | D3: Assignment | E3: Summary
B5: Alternative:
A9: TRIPS | B9: BY | C9: TOD | D9: AND | E9: MODE | F9: (MODE | G9: CHOICE | H9: MODEL | I9: RESULTS)
A10: |
B11: Per | C11: DriveAlo | D11: ShrRide | E11: 2 | F11: ShrRide | G11: 3+ | H11: WalkLocal | I11: WalkBrt | J11: WalkExpBus | K11: WalkUrbRail | L11: WalkComRail | M11: PnRLocal | N11: PnRBrt | O11: PnRExpBus | P11: PnRUrbRail | Q11: PnRComRail | R11: KnRLocal | S11: KnRBrt | T11: KnRExpBus | U11: KnRUrbRail | V11: KnrComRail | W11: | | X11: Total | Y11: Trips
A12: |
B13: AM | C13: -- | D13: -- | E13: -- | F13: 5175 | G13: 42 | H13: 41 | I13: 0 | J13: 277 | K13: 1169 | L13: 0 | M13: 5 | N13: 0 | O13: 22 | P13: 0 | Q13: 0 | R13: 0 | S13: 0 | T13: 0 | U13: | | V13: --
B14: MD | C14: -- | D14: -- | E14: -- | F14: 7578 | G14: 19 | H14: 56 | I14: 0 | J14: 0 | K14: 624 | L14: 0 | M14: 2 | N14: 0 | O14: 0 | P14: 0 | Q14: 0 | R14: 0 | S14: 0 | T14: 0 | U14: | | V14: --
B15: PM | C15: -- | D15: -- | E15: -- | F15: 7274 | G15: 24 | H15: 49 | I15: 0 | J15: 928 | K15: 1282 | L15: 0 | M15: 7 | N15: 0 | O15: 16 | P15: 0 | Q15: 0 | R15: 0 | S15: 0 | T15: 0 | U15: | | V15: --
B16: OP | C16: -- | D16: -- | E16: -- | F16: 2690 | G16: 0 | H16: 17 | I16: 0 | J16: 0 | K16: 209 | L16: 0 | M16: 0 | N16: 0 | O16: 0 | P16: 0 | Q16: 0 | R16: 0 | S16: 0 | T16: 0 | U16: | | V16: --
A17: |
A18: TOTAL | B18: -- | C18: -- | D18: -- | E18: 22717 | F18: 85 | G18: 163 | H18: 0 | I18: 1205 | J18: 3284 | K18: 0 | L18: 14 | M18: 0 | N18: 38 | O18: 0 | P18: 0 | Q18: 0 | R18: 0 | S18: 0 | T18: | | U18: --
A22: TRANSIT | B22: BOARDINGS | C22: BY | D22: MODE | E22: (TRANSIT | F22: ASSIGNMENT | G22: RESULTS)
A23: |
B24: Mode | C24: Mode | D24: Name | E24: Dwell | F24: Factor | G24: AM | H24: MD | I24: PM | J24: OP | K24: | | L24: Total
A25: |
B26: 1 | C26: Local | D26: 2 | E26: 8366 | F26: 11296 | G26: 11776 | H26: 3950 | I26: | | J26: 35396
B27: 6 | C27: Express | D27: Bus | E27: 1 | F27: 46 | G27: 58 | H27: 56 | I27: 18 | J27: | | K27: 180
B28: 7 | C28: Commuter | D28: Bus | E28: 1 | F28: 3 | G28: 0 | H28: 4 | I28: 0 | J28: | | K28: 7
B29: 8 | C29: Existing | D29: BRT | E29: 1.5 | F29: 44 | G29: 18 | H29: 85 | I29: 0 | J29: | | K29: 147
B30: 11 | C30: Shuttle | D30: 2 | E30: 267 | F30: 0 | G30: 923 | H30: 0 | I30: | | J30: 1191
B31: 12 | C31: ComRail | D31: 0.5 | E31: 30 | F31: 0 | G31: 12 | H31: 0 | I31: | | J31: 40
A32: |
B33: TOTAL | C33: 8756 | D33: 11372 | E33: 12856 | F33: 3968 | G33: | | H33: 36961
A37: TRANSFER | B37: RATES | C37: BY | D37: TOD
B39: Period | C39: Transfers | D39: (Rate)
B41: AM | C41: 2025 | D41: (30.08%)
B42: MD | C42: 3093 | D42: (37.35%)
B43: PM | C43: 3276 | D43: (34.19%)
B44: OP | C44: 1052 | D44: (36.06%)
B46: TOTAL | C46: 9455 | D46: (34.37%)
A50: TRANSIT | B50: BOARDINGS | C50: BY | D50: ROUTE | E50: (TRANSIT | F50: ASSIGNMENT | G50: RESULTS)
A51: |
B52: Route | C52: Mode | D52: Route | E52: Name | F52: AM | G52: MD | H52: PM | I52: OP | J52: | | K52: Total
A53: |
B54: 3 | C54: 1 | D54: Rte | E54: 3 | F54: 1986 | G54: 2285 | H54: 3002 | I54: 782 | J54: | | K54: 8057
B55: 4 | C55: 1 | D55: Rte | E55: 4 | F55: 50 | G55: 78 | H55: 88 | I55: 84 | J55: | | K55: 299
B56: 6 | C56: 1 | D56: Rte | E56: 6 | F56: 155 | G56: 109 | H56: 286 | I56: 72 | J56: | | K56: 622
B57: 7 | C57: 1 | D57: Rte | E57: 7 | F57: 555 | G57: 1056 | H57: 749 | I57: 295 | J57: | | K57: 2656
...

Sheet Obs_Ridership
A1: Model Rte txt+A36 | B1: Model Rte num | C1: Modelid | D1: Model Rte Name | E1: Ridership Oct 2023 | F1: Daily_20 | G1: Daily_22
A2: 3 | B2: 3 | C2: 35 | D2: Rte 3 West End (Bellevue) IB | E2: 55372 | F2: 2768.6 | G2: 2516.9091
A3: 4 | B3: 4 | C3: 17 | D3: Rte 4 Shelby IB | E3: 20703 | F3: 1035.15 | G3: 941.04545
A4: 6 | B4: 6 | C4: 74 | D4: Rte 6 Lebanon Rd IB | E4: 18000 | F4: 900 | G4: 818.18182
A5: 7 | B5: 7 | C5: 37 | D5: Rte 7 Hillsboro IB | E5: 40515 | F5: 2025.75 | G5: 1841.5909
A6: 8 | B6: 8 | C6: 32 | D6: Rte 8 8TH AVENUE SOUTH iB | E6: 20777 | F6: 1038.85 | G6: 944.40909
A7: 9 | B7: 9 | C7: 51 | D7: Rte 9 MetroCenter IB | E7: 7713 | F7: 385.65 | G7: 350.59091
A8: 14 | B8: 14 | C8: 29 | D8: Rte 14 WHITES CREEK iB | E8: 7352 | F8: 367.6 | G8: 334.18182
A9: 17 | B9: 17 | C9: 2 | D9: Rte 17 12TH AVENUE SOUTH iB | E9: 14035 | F9: 701.75 | G9: 637.95455
A10: 18 | B10: 18 | C10: 78 | D10: Rte 18 Airport Exp IB | E10: 14914 | F10: 745.7 | G10: 677.90909
A11: 19 | B11: 19 | C11: 49 | D11: Rte 19 Herman IB | E11: 21026 | F11: 1051.3 | G11: 955.72727
A12: 22 | B12: 22 | C12: 60 | D12: Rte 22 Bordeaux (Kings Ln) IB | E12: 33119 | F12: 1655.95 | G12: 1505.4091
A13: 23 | B13: 23 | C13: 15 | D13: Rte 23 Dickerson Pike IB | E13: 59191 | F13: 2959.55 | G13: 2690.5
... A35: 95 | B35: 95 | C35: 72 | D35: Rte 95 Spring Hill Exp IB | E35: 1136 | F35: 56.8 | G35: 51.636364
D36: Rover | E36: 9187 | F36: 459.35 | G36: 417.59091
D37: FTA | E37: 12084 | F37: 604.2 | G37: 549.27273
D38: Mule
D40: TOTAL | E40: 778330 | F40: 38916.5 | G40: 35378.636
F41: 38916.5 | G41: check monthly weekday/20
F42: =E40/20 -> 38916.5

Sheet BoardingByRoute_ABM
B1: Route | C1: Mode | D1: Route Name | F1: AM | G1: MD | H1: PM | I1: OP | | J1: T | K1: otal | M1: text | N1: Boarding
B2: =TrnStat.asc!B54 -> 3 | C2: =TrnStat.asc!C54 -> 1 | D2: =TrnStat.asc!D54 -> Rte | E2: =TrnStat.asc!E54 -> 3 | F2: =TrnStat.asc!F54 -> 1986 | G2: =TrnStat.asc!G54 -> 2285 | H2: =TrnStat.asc!H54 -> 3002 | I2: =TrnStat.asc!I54 -> 782 | ... K2: =TrnStat.asc!K54 -> 8057 | M2: =IF(ISNUMBER(K2),K2,CONCATENATE(LEFT(K2,2),RIGHT(K2,3))) -> 8057 | N2: =VALUE(M2) -> 8057
B3: =TrnStat.asc!B55 -> 4 | C3: =TrnStat.asc!C55 -> 1 | D3: =TrnStat.asc!D55 -> Rte | E3: =TrnStat.asc!E55 -> 4 | F3: =TrnStat.asc!F55 -> 50 | G3: =TrnStat.asc!G55 -> 78 | H3: =TrnStat.asc!H55 -> 88 | I3: =TrnStat.asc!I55 -> 84 | ... K3: =TrnStat.asc!K55 -> 299 | M3: =IF(ISNUMBER(K3),K3,CONCATENATE(LEFT(K3,2),RIGHT(K3,3))) -> 299 | N3: =VALUE(M3) -> 299
B4: =TrnStat.asc!B56 -> 6 | C4: =TrnStat.asc!C56 -> 1 | D4: =TrnStat.asc!D56 -> Rte | E4: =TrnStat.asc!E56 -> 6 | F4: =TrnStat.asc!F56 -> 155 | G4: =TrnStat.asc!G56 -> 109 | H4: =TrnStat.asc!H56 -> 286 | I4: =TrnStat.asc!I56 -> 72 | ... K4: =TrnStat.asc!K56 -> 622 | M4: =IF(ISNUMBER(K4),K4,CONCATENATE(LEFT(K4,2),RIGHT(K4,3))) -> 622 | N4: =VALUE(M4) -> 622
B5: =TrnStat.asc!B57 -> 7 | C5: =TrnStat.asc!C57 -> 1 | D5: =TrnStat.asc!D57 -> Rte | E5: =TrnStat.asc!E57 -> 7 | F5: =TrnStat.asc!F57 -> 555 | G5: =TrnStat.asc!G57 -> 1056 | H5: =TrnStat.asc!H57 -> 749 | I5: =TrnStat.asc!I57 -> 295 | ... K5: =TrnStat.asc!K57 -> 2656 | M5: =IF(ISNUMBER(K5),K5,CONCATENATE(LEFT(K5,2),RIGHT(K5,3))) -> 2656 | N5: =VALUE(M5) -> 2656
B6: =TrnStat.asc!B58 -> 8 | C6: =TrnStat.asc!C58 -> 1 | D6: =TrnStat.asc!D58 -> Rte | E6: =TrnStat.asc!E58 -> 8 | F6: =TrnStat.asc!F58 -> 226 | G6: =TrnStat.asc!G58 -> 309 | H6: =TrnStat.asc!H58 -> 240 | I6: =TrnStat.asc!I58 -> 65 | ... K6: =TrnStat.asc!K58 -> 839 | M6: =IF(ISNUMBER(K6),K6,CONCATENATE(LEFT(K6,2),RIGHT(K6,3))) -> 839 | N6: =VALUE(M6) -> 839
B7: =TrnStat.asc!B59 -> 9 | C7: =TrnStat.asc!C59 -> 1 | D7: =TrnStat.asc!D59 -> Rte | E7: =TrnStat.asc!E59 -> 9 | F7: =TrnStat.asc!F59 -> 259 | G7: =TrnStat.asc!G59 -> 336 | H7: =TrnStat.asc!H59 -> 239 | I7: =TrnStat.asc!I59 -> 0 | ... K7: =TrnStat.asc!K59 -> 834 | M7: =IF(ISNUMBER(K7),K7,CONCATENATE(LEFT(K7,2),RIGHT(K7,3))) -> 834 | N7: =VALUE(M7) -> 834
B8: =TrnStat.asc!B60 -> 14 | C8: =TrnStat.asc!C60 -> 1 | D8: =TrnStat.asc!D60 -> Rte | E8: =TrnStat.asc!E60 -> 14 | F8: =TrnStat.asc!F60 -> 96 | G8: =TrnStat.asc!G60 -> 63 | H8: =TrnStat.asc!H60 -> 138 | I8: =TrnStat.asc!I60 -> 30 | ... K8: =TrnStat.asc!K60 -> 328 | M8: =IF(ISNUMBER(K8),K8,CONCATENATE(LEFT(K8,2),RIGHT(K8,3))) -> 328 | N8: =VALUE(M8) -> 328
B9: =TrnStat.asc!B61 -> 17 | C9: =TrnStat.asc!C61 -> 1 | D9: =TrnStat.asc!D61 -> Rte | E9: =TrnStat.asc!E61 -> 17 | F9: =TrnStat.asc!F61 -> 230 | G9: =TrnStat.asc!G61 -> 277 | H9: =TrnStat.asc!H61 -> 322 | I9: =TrnStat.asc!I61 -> 56 | ... K9: =TrnStat.asc!K61 -> 886 | M9: =IF(ISNUMBER(K9),K9,CONCATENATE(LEFT(K9,2),RIGHT(K9,3))) -> 886 | N9: =VALUE(M9) -> 886
B10: =TrnStat.asc!B62 -> 18 | C10: =TrnStat.asc!C62 -> 6 | D10: =TrnStat.asc!D62 -> Rte | E10: =TrnStat.asc!E62 -> 18 | F10: =TrnStat.asc!F62 -> 66 | G10: =TrnStat.asc!G62 -> 172 | H10: =TrnStat.asc!H62 -> 72 | I10: =TrnStat.asc!I62 -> 46 | ... K10: =TrnStat.asc!K62 -> 358 | M10: =IF(ISNUMBER(K10),K10,CONCATENATE(LEFT(K10,2),RIGHT(K10,3))) -> 358 | N10: =VALUE(M10) -> 358
B11: =TrnStat.asc!B63 -> 19 | C11: =TrnStat.asc!C63 -> 1 | D11: =TrnStat.asc!D63 -> Rte | E11: =TrnStat.asc!E63 -> 19 | F11: =TrnStat.asc!F63 -> 232 | G11: =TrnStat.asc!G63 -> 294 | H11: =TrnStat.asc!H63 -> 425 | I11: =TrnStat.asc!I63 -> 101 | ... K11: =TrnStat.asc!K63 -> 1053 | M11: =IF(ISNUMBER(K11),K11,CONCATENATE(LEFT(K11,2),RIGHT(K11,3))) -> 1053 | N11: =VALUE(M11) -> 1053
B12: =TrnStat.asc!B64 -> 22 | C12: =TrnStat.asc!C64 -> 1 | D12: =TrnStat.asc!D64 -> Rte | E12: =TrnStat.asc!E64 -> 22 | F12: =TrnStat.asc!F64 -> 274 | G12: =TrnStat.asc!G64 -> 526 | H12: =TrnStat.asc!H64 -> 539 | I12: =TrnStat.asc!I64 -> 358 | ... K12: =TrnStat.asc!K64 -> 1697 | M12: =IF(ISNUMBER(K12),K12,CONCATENATE(LEFT(K12,2),RIGHT(K12,3))) -> 1697 | N12: =VALUE(M12) -> 1697
B13: =TrnStat.asc!B65 -> 23 | C13: =TrnStat.asc!C65 -> 1 | D13: =TrnStat.asc!D65 -> Rte | E13: =TrnStat.asc!E65 -> 23 | F13: =TrnStat.asc!F65 -> 382 | G13: =TrnStat.asc!G65 -> 566 | H13: =TrnStat.asc!H65 -> 520 | I13: =TrnStat.asc!I65 -> 182 | ... K13: =TrnStat.asc!K65 -> 1650 | M13: =IF(ISNUMBER(K13),K13,CONCATENATE(LEFT(K13,2),RIGHT(K13,3))) -> 1650 | N13: =VALUE(M13) -> 1650
... B34: =TrnStat.asc!B86 -> 95 | C34: =TrnStat.asc!C86 -> 6 | D34: =TrnStat.asc!D86 -> Rte | E34: =TrnStat.asc!E86 -> 95 | F34: =TrnStat.asc!F86 -> 5 | G34: =TrnStat.asc!G86 -> 0 | H34: =TrnStat.asc!H86 -> 4 | I34: =TrnStat.asc!I86 -> 0 | ... K34: =TrnStat.asc!K86 -> 11 | M34: =IF(ISNUMBER(K34),K34,CONCATENATE(LEFT(K34,2),RIGHT(K34,3))) -> 11 | N34: =VALUE(M34) -> 11

Sheet OBS_RteName
A1: Rte ID | B1: Route Name
A2: 3 | B2: Rte 3 West End (Bellevue) IB
A3: 4 | B3: Rte 4 Shelby IB
A4: 6 | B4: Rte 6 Lebanon Rd IB
A5: 7 | B5: Rte 7 Hillsboro IB
A6: 8 | B6: Rte 8 8TH AVENUE SOUTH iB
A7: 9 | B7: Rte 9 MetroCenter IB
A8: 14 | B8: Rte 14 WHITES CREEK iB
A9: 17 | B9: Rte 17 12TH AVENUE SOUTH iB
A10: 18 | B10: Rte 18 Airport Exp IB
A11: 19 | B11: Rte 19 Herman IB
A12: 22 | B12: Rte 22 Bordeaux (Kings Ln) IB
A13: 23 | B13: Rte 23 Dickerson Pike IB
... A35: 95 | B35: Rte 95 Spring Hill Exp IB

Sheet ABM_RteName
A1: Route Id | B1: Route Name (RAW) | C1: Route Name (Temp) | D1: Route Name | E1: Mode | F1: Track | I1: RouteNum | J1: Route_Name | K1: modes | L1: Mode | M1: Track
A2: 3 | B2: =VLOOKUP(A2,Obs_Ridership!$B:$D,3,FALSE) -> Rte 3 West End (Bellevue) IB | C2: =VLOOKUP(A2,$I:$L,2,FALSE) -> Rte 3 West End (White Bridge) IB | D2: =IF(ISNUMBER(SEARCH("IB",B2)),LEFT(B2,LEN(B2)-3),IF(ISNUMBER(SEARCH("OB",B2)),LEFT(B2,LEN(B2)-3),B2)) -> Rte 3 West End (Bellevue) | E2: =VLOOKUP($B2,$J:$L,3,FALSE) -> 1 | F2: =VLOOKUP($B2,$J:$M,4,FALSE) -> 54 | I2: 3 | J2: Rte 3 West End (White Bridge) IB | K2: 4 | L2: 1 | M2: 55
A3: 4 | B3: =VLOOKUP(A3,Obs_Ridership!$B:$D,3,FALSE) -> Rte 4 Shelby IB | C3: =VLOOKUP(A3,$I:$L,2,FALSE) -> Rte 4 Shelby IB | D3: =IF(ISNUMBER(SEARCH("IB",B3)),LEFT(B3,LEN(B3)-3),IF(ISNUMBER(SEARCH("OB",B3)),LEFT(B3,LEN(B3)-3),B3)) -> Rte 4 Shelby | E3: =VLOOKUP($B3,$J:$L,3,FALSE) -> 1 | F3: =VLOOKUP($B3,$J:$M,4,FALSE) -> 57 | I3: 3 | J3: Rte 3 West End (Bellevue) IB | K3: 4 | L3: 1 | M3: 54
A4: 6 | B4: =VLOOKUP(A4,Obs_Ridership!$B:$D,3,FALSE) -> Rte 6 Lebanon Rd IB | C4: =VLOOKUP(A4,$I:$L,2,FALSE) -> Rte 6 Lebanon Rd OB | D4: =IF(ISNUMBER(SEARCH("IB",B4)),LEFT(B4,LEN(B4)-3),IF(ISNUMBER(SEARCH("OB",B4)),LEFT(B4,LEN(B4)-3),B4)) -> Rte 6 Lebanon Rd | E4: =VLOOKUP($B4,$J:$L,3,FALSE) -> 1 | F4: =VLOOKUP($B4,$J:$M,4,FALSE) -> 67 | I4: 3 | J4: Rte 3 West End (Bellevue) oB | K4: 4 | L4: 1 | M4: 54
A5: 7 | B5: =VLOOKUP(A5,Obs_Ridership!$B:$D,3,FALSE) -> Rte 7 Hillsboro IB | C5: =VLOOKUP(A5,$I:$L,2,FALSE) -> Rte 7 Hillsboro IB | D5: =IF(ISNUMBER(SEARCH("IB",B5)),LEFT(B5,LEN(B5)-3),IF(ISNUMBER(SEARCH("OB",B5)),LEFT(B5,LEN(B5)-3),B5)) -> Rte 7 Hillsboro | E5: =VLOOKUP($B5,$J:$L,3,FALSE) -> 1 | F5: =VLOOKUP($B5,$J:$M,4,FALSE) -> 68 | I5: 3 | J5: Rte 3 West End (White Bridge) OB | K5: 4 | L5: 1 | M5: 55
A6: 8 | B6: =VLOOKUP(A6,Obs_Ridership!$B:$D,3,FALSE) -> Rte 8 8TH AVENUE SOUTH iB | C6: =VLOOKUP(A6,$I:$L,2,FALSE) -> Rte 8 8TH AVENUE SOUTH iB | D6: =IF(ISNUMBER(SEARCH("IB",B6)),LEFT(B6,LEN(B6)-3),IF(ISNUMBER(SEARCH("OB",B6)),LEFT(B6,LEN(B6)-3),B6)) -> Rte 8 8TH AVENUE SOUTH | E6: =VLOOKUP($B6,$J:$L,3,FALSE) -> 1 | F6: =VLOOKUP($B6,$J:$M,4,FALSE) -> 73 | I6: 4 | J6: Rte 4 Shelby IB | K6: 4 | L6: 1 | M6: 57
A7: 9 | B7: =VLOOKUP(A7,Obs_Ridership!$B:$D,3,FALSE) -> Rte 9 MetroCenter IB | C7: =VLOOKUP(A7,$I:$L,2,FALSE) -> Rte 9 MetroCenter OB | D7: =IF(ISNUMBER(SEARCH("IB",B7)),LEFT(B7,LEN(B7)-3),IF(ISNUMBER(SEARCH("OB",B7)),LEFT(B7,LEN(B7)-3),B7)) -> Rte 9 MetroCenter | E7: =VLOOKUP($B7,$J:$L,3,FALSE) -> 1 | F7: =VLOOKUP($B7,$J:$M,4,FALSE) -> 78 | I7: 4 | J7: Rte 4 Shelby OB | K7: 4 | L7: 1 | M7: 57
A8: 14 | B8: =VLOOKUP(A8,Obs_Ridership!$B:$D,3,FALSE) -> Rte 14 WHITES CREEK iB | C8: =VLOOKUP(A8,$I:$L,2,FALSE) -> Rte 14 WHITES CREEK oB | D8: =IF(ISNUMBER(SEARCH("IB",B8)),LEFT(B8,LEN(B8)-3),IF(ISNUMBER(SEARCH("OB",B8)),LEFT(B8,LEN(B8)-3),B8)) -> Rte 14 WHITES CREEK | E8: =VLOOKUP($B8,$J:$L,3,FALSE) -> 1 | F8: =VLOOKUP($B8,$J:$M,4,FALSE) -> 42 | I8: 6 | J8: Rte 6 Lebanon Rd OB | K8: 4 | L8: 1 | M8: 67
A9: 17 | B9: =VLOOKUP(A9,Obs_Ridership!$B:$D,3,FALSE) -> Rte 17 12TH AVENUE SOUTH iB | C9: =VLOOKUP(A9,$I:$L,2,FALSE) -> Rte 17 12TH AVENUE SOUTH iB | D9: =IF(ISNUMBER(SEARCH("IB",B9)),LEFT(B9,LEN(B9)-3),IF(ISNUMBER(SEARCH("OB",B9)),LEFT(B9,LEN(B9)-3),B9)) -> Rte 17 12TH AVENUE SOUTH | E9: =VLOOKUP($B9,$J:$L,3,FALSE) -> 1 | F9: =VLOOKUP($B9,$J:$M,4,FALSE) -> 43 | I9: 6 | J9: Rte 6 Lebanon Rd IB | K9: 4 | L9: 1 | M9: 67
A10: 18 | B10: =VLOOKUP(A10,Obs_Ridership!$B:$D,3,FALSE) -> Rte 18 Airport Exp IB | C10: =VLOOKUP(A10,$I:$L,2,FALSE) -> Rte 18 Airport Exp OB | D10: =IF(ISNUMBER(SEARCH("IB",B10)),LEFT(B10,LEN(B10)-3),IF(ISNUMBER(SEARCH("OB",B10)),LEFT(B10,LEN(B10)-3),B10)) -> Rte 18 Airport Exp | E10: =VLOOKUP($B10,$J:$L,3,FALSE) -> 6 | F10: =VLOOKUP($B10,$J:$M,4,FALSE) -> 44 | I10: 7 | J10: Rte 7 Hillsboro IB | K10: 4 | L10: 1 | M10: 68
A11: 19 | B11: =VLOOKUP(A11,Obs_Ridership!$B:$D,3,FALSE) -> Rte 19 Herman IB | C11: =VLOOKUP(A11,$I:$L,2,FALSE) -> Rte 19 Herman IB | D11: =IF(ISNUMBER(SEARCH("IB",B11)),LEFT(B11,LEN(B11)-3),IF(ISNUMBER(SEARCH("OB",B11)),LEFT(B11,LEN(B11)-3),B11)) -> Rte 19 Herman | E11: =VLOOKUP($B11,$J:$L,3,FALSE) -> 1 | F11: =VLOOKUP($B11,$J:$M,4,FALSE) -> 46 | I11: 7 | J11: Rte 7 Hillsboro OB | K11: 4 | L11: 1 | M11: 68
A12: 22 | B12: =VLOOKUP(A12,Obs_Ridership!$B:$D,3,FALSE) -> Rte 22 Bordeaux (Kings Ln) IB | C12: =VLOOKUP(A12,$I:$L,2,FALSE) -> Rte 22 Bordeaux (Panaroma) IB | D12: =IF(ISNUMBER(SEARCH("IB",B12)),LEFT(B12,LEN(B12)-3),IF(ISNUMBER(SEARCH("OB",B12)),LEFT(B12,LEN(B12)-3),B12)) -> Rte 22 Bordeaux (Kings Ln) | E12: =VLOOKUP($B12,$J:$L,3,FALSE) -> 1 | F12: =VLOOKUP($B12,$J:$M,4,FALSE) -> 47 | I12: 8 | J12: Rte 8 8TH AVENUE SOUTH iB | K12: 4 | L12: 1 | M12: 73
A13: 23 | B13: =VLOOKUP(A13,Obs_Ridership!$B:$D,3,FALSE) -> Rte 23 Dickerson Pike IB | C13: =VLOOKUP(A13,$I:$L,2,FALSE) -> Rte 23 Dickerson Pike OB | D13: =IF(ISNUMBER(SEARCH("IB",B13)),LEFT(B13,LEN(B13)-3),IF(ISNUMBER(SEARCH("OB",B13)),LEFT(B13,LEN(B13)-3),B13)) -> Rte 23 Dickerson Pike | E13: =VLOOKUP($B13,$J:$L,3,FALSE) -> 1 | F13: =VLOOKUP($B13,$J:$M,4,FALSE) -> 49 | I13: 8 | J13: Rte 8 8TH AVENUE SOUTH oB | K13: 4 | L13: 1 | M13: 73
... A35: 95 | B35: =VLOOKUP(A35,Obs_Ridership!$B:$D,3,FALSE) -> Rte 95 Spring Hill Exp IB | C35: =VLOOKUP(A35,$I:$L,2,FALSE) -> Rte 95 Spring Hill Exp OB | D35: =IF(ISNUMBER(SEARCH("IB",B35)),LEFT(B35,LEN(B35)-3),IF(ISNUMBER(SEARCH("OB",B35)),LEFT(B35,LEN(B35)-3),B35)) -> Rte 95 Spring Hill Exp | E35: =VLOOKUP($B35,$J:$L,3,FALSE) -> 6 | F35: =VLOOKUP($B35,$J:$M,4,FALSE) -> 81 | I35: 24 | J35: Rte 24 Bellevue Exp PM | K35: 5 | L35: 6 | M35: 51
I36: 28 | J36: Rte 28 Meridian IB | K36: 4 | L36: 1 | M36: 52
I37: 28 | J37: Rte 28 Meridian OB | K37: 4 | L37: 1 | M37: 52
I38: 29 | J38: Rte 29 Jefferson IB | K38: 4 | L38: 1 | M38: 53
I39: 29 | J39: Rte 29 Jefferson OB | K39: 4 | L39: 1 | M39: 53
I40: 34 | J40: Rte 34 Opry Mills IB | K40: 4 | L40: 1 | M40: 56
I41: 34 | J41: Rte 34 Opry Mills OB | K41: 4 | L41: 1 | M41: 56
I42: 41 | J42: Rte 41 Golden Valley OB PM | K42: 4 | L42: 1 | M42: 59
I43: 41 | J43: Rte 41 Golden Valley IB AM | K43: 4 | L43: 1 | M43: 58
I44: 41 | J44: Rte 41 Golden Valley IB PM | K44: 4 | L44: 1 | M44: 59
I45: 41 | J45: Rte 41 Golden Valley OB AM | K45: 4 | L45: 1 | M45: 58
I46: 42 | J46: Rte 42 St. Cecilia/Cumberland IB | K46: 4 | L46: 1 | M46: 60
I47: 42 | J47: Rte 42 St. Cecilia/Cumberland oB | K47: 4 | L47: 1 | M47: 60
... I96: 112 | J96: Rte 112 FTA Red Route NS | K96: 4 | L96: 3 | M96: 41
J97: MuleGreenWest | K97: 4 | L97: 2 | M97: 25
J98: MulePurpleEast | K98: 4 | L98: 2 | M98: 26
J99: MuleRedSouth | K99: 4 | L99: 2 | M99: 27
J100: MuleBlueSB | K100: 4 | L100: 2 | M100: 24
J101: Circ_Lebanon_W | K101: 4 | L101: 2 | M101: 18
J102: Circ_Lebanon_E | K102: 4 | L102: 2 | M102: 15
J103: Circ_Lebanon_N | K103: 4 | L103: 2 | M103: 16
J104: Circ_Lebanon_S | K104: 4 | L104: 2 | M104: 17
J105: Circ_MJ_E | K105: 4 | L105: 2 | M105: 19
J106: Circ_MJ_W | K106: 4 | L106: 2 | M106: 22
J107: Circ_MJ_S | K107: 4 | L107: 2 | M107: 21
J108: Circ_MJ_N | K108: 4 | L108: 2 | M108: 20
... J144: BRT_CU1_Corridor iB | K144: 7 | L144: 9 | M144: 3
