Workbook

Sheet BoardingByRoute_All
D1: BOARDINGS BY SUB-MODE
E2: OBS | G2: ABM | I2: DIFF | K2: Sub-mode Constant (DaySim) | N2: NOTE:
C3: Mode | D3: Transit sub-mode | E3: Count | F3: Percentage | G3: Count | H3: Percentage | I3: Count | J3: Percentage | K3: Utils | L3: Mins | N3: diff in by sub-mode in TrnStat.asc and this table is because of Rte 18 Airport Exp. There are two servies, one is Exp and one local. TrnStat.asc considers both as local. | AX3: Path Impedance
C4: 1 | D4: Local Bus | E4: =SUMIF($A$15:$A$48,1,E$15:E$49)+SUMIF($A$15:$A$48,2,E$15:E$49) | F4: =E4/E$8 | G4: =SUMIF($A$15:$A$48,1,G$15:G$48)+SUMIF($A$15:$A$48,2,G$15:G$48) | H4: =PrilimTable!F57 | I4: =G4-E4 | J4: =I4/E4 | K4: =PrilimTable!G57 | L4: =PrilimTable!H57 | AX4: PathImpedance_TransitLocalBusPathConstant = 0.05
C5: 6,7 | D5: Express Bus | E5: =SUMIF($A$15:$A$48,6,E$15:E$49)+SUMIF($A$15:$A$48,7,E$15:E$49) | F5: =E5/E$8 | G5: =SUMIF($A$15:$A$48,6,G$15:G$48)+SUMIF($A$15:$A$48,7,G$15:G$48) | H5: =PrilimTable!F58 | I5: =G5-E5 | J5: =I5/E5 | K5: =PrilimTable!G58 | L5: =PrilimTable!H58 | AX5: PathImpedance_TransitPremiumBusPathConstant = 0.12
C6: 8 | D6: BRT | E6: =SUMIF($A$15:$A$48,8,E$15:E$49) | F6: =E6/E$8 | G6: =SUMIF($A$15:$A$48,8,G$15:G$48) | H6: =PrilimTable!F59 | I6: =G6-E6 | J6: =I6/E6 | K6: =PrilimTable!G59 | L6: =PrilimTable!H59 | AX6: PathImpedance_TransitLightRailPathConstant = 0.0
C7: 11,12 | D7: Commuter Rail | E7: =SUMIF($A$15:$A$48,11,E$15:E$49)+SUMIF($A$15:$A$48,12,E$15:E$49) | F7: =E7/E$8 | G7: =SUMIF($A$15:$A$48,11,G$15:G$48)+SUMIF($A$15:$A$48,12,G$15:G$48) | H7: =PrilimTable!F60 | I7: =G7-E7 | J7: =I7/E7 | K7: =PrilimTable!G60 | L7: =PrilimTable!H60 | AX7: PathImpedance_TransitCommuterRailPathConstant = 1.15
D8: Total | E8: =SUM(E4:E7) | F8: =E8/E$8 | G8: =SUM(G4:G7) | H8: 1 | I8: =G8-E8 | J8: =I8/E8 | AX8: PathImpedance_TransitFerryPathConstant = 0.07
D9: Transit trips | E9: 25693 | G9: 23765 | AX9: PathImpedance_TransitUsePathTypeSpecificTime = true
D10: Boarding rate | E10: =E8/E9 | G10: =G8/G9 | K10: Transfer Rate | L10: =PrilimTable!E63
D11: R-Squared | E11: =RSQ(G15:G48,E15:E48) | AX11: PathImpedance_TransitPremiumBusTimeAdditiveWeight = -0.204
B12: BOARDINGS BY ROUTE | X12: BOARDINGS BY ROUTE (SORTED BY OBS BOARDINGS) | AX12: PathImpedance_TransitLightRailTimeAdditiveWeight = 0.0
E13: OBS | G13: ABM | I13: DIFF | AA13: OBS | AC13: =G13 | AE13: DIFF | AX13: PathImpedance_TransitCommuterRailTimeAdditiveWeight = -0.273
A14: Mode | B14: Rte Id (OBS) | C14: Rte Id (ABM) | D14: Rte Name | E14: Boardings | F14: Percentage | G14: Boardings | H14: Percentage | I14: Diff | J14: % Diff | X14: Rte Id (OBS) | Y14: Rte Id (ABM) | Z14: Rte Name | AA14: Boardings | AB14: Percentage | AC14: Boardings | AD14: Percentage | AE14: Diff | AF14: % Diff | AG14: Reference | AX14: PathImpedance_TransitFerryTimeAdditiveWeight = -0.318
A15: =VLOOKUP($C15,PrilimTable!$O:$U,7,FALSE) | B15: 3 | C15: =B15 | D15: =VLOOKUP($C15,PrilimTable!$O:$T,2,FALSE) | E15: =SUMIF(PrilimTable!$N$4:$N$82,B15,PrilimTable!$Q$4:$Q$82) | F15: =E15/$E$49 | G15: =SUMIF(PrilimTable!$O$4:$O$82,C15,PrilimTable!$S$4:$S$82) | H15: =G15/$G$49 | I15: =G15-E15 | J15: =I15/E15 | X15: 3 | Y15: 3 | Z15: =VLOOKUP(Y15,$C$14:$D$49,2,FALSE) | AA15: =SUMIF(PrilimTable!$N$4:$N$82,X15,PrilimTable!$Q$4:$Q$82) | AB15: =AA15/$E$49 | AC15: =SUMIF(PrilimTable!$O$4:$O$82,Y15,PrilimTable!$S$4:$S$82) | AD15: =AC15/$G$49 | AE15: =AC15-AA15 | AF15: =AE15/AA15 | AG15: 100
A16: =VLOOKUP($C16,PrilimTable!$O:$U,7,FALSE) | B16: 4 | C16: =B16 | D16: =VLOOKUP($C16,PrilimTable!$O:$T,2,FALSE) | E16: =SUMIF(PrilimTable!$N$4:$N$82,B16,PrilimTable!$Q$4:$Q$82) | F16: =E16/$E$49 | G16: =SUMIF(PrilimTable!$O$4:$O$82,C16,PrilimTable!$S$4:$S$82) | H16: =G16/$G$49 | I16: =G16-E16 | J16: =I16/E16 | X16: 4 | Y16: 4 | Z16: =VLOOKUP(Y16,$C$14:$D$49,2,FALSE) | AA16: =SUMIF(PrilimTable!$N$4:$N$82,X16,PrilimTable!$Q$4:$Q$82) | AB16: =AA16/$E$49 | AC16: =SUMIF(PrilimTable!$O$4:$O$82,Y16,PrilimTable!$S$4:$S$82) | AD16: =AC16/$G$49 | AE16: =AC16-AA16 | AF16: =AE16/AA16 | AG16: 200 | AX16: PathImpedance_TransitPremiumBusInVehicleTimeWeight = 0.95
A17: =VLOOKUP($C17,PrilimTable!$O:$U,7,FALSE) | B17: 6 | C17: =B17 | D17: =VLOOKUP($C17,PrilimTable!$O:$T,2,FALSE) | E17: =SUMIF(PrilimTable!$N$4:$N$82,B17,PrilimTable!$Q$4:$Q$82) | F17: =E17/$E$49 | G17: =SUMIF(PrilimTable!$O$4:$O$82,C17,PrilimTable!$S$4:$S$82) | H17: =G17/$G$49 | I17: =G17-E17 | J17: =I17/E17 | X17: 6 | Y17: 6 | Z17: =VLOOKUP(Y17,$C$14:$D$49,2,FALSE) | AA17: =SUMIF(PrilimTable!$N$4:$N$82,X17,PrilimTable!$Q$4:$Q$82) | AB17: =AA17/$E$49 | AC17: =SUMIF(PrilimTable!$O$4:$O$82,Y17,PrilimTable!$S$4:$S$82) | AD17: =AC17/$G$49 | AE17: =AC17-AA17 | AF17: =AE17/AA17 | AG17: 300 | AX17: PathImpedance_TransitLightRailInVehicleTimeWeight = 1.0
A18: =VLOOKUP($C18,PrilimTable!$O:$U,7,FALSE) | B18: 7 | C18: =B18 | D18: =VLOOKUP($C18,PrilimTable!$O:$T,2,FALSE) | E18: =SUMIF(PrilimTable!$N$4:$N$82,B18,PrilimTable!$Q$4:$Q$82) | F18: =E18/$E$49 | G18: =SUMIF(PrilimTable!$O$4:$O$82,C18,PrilimTable!$S$4:$S$82) | H18: =G18/$G$49 | I18: =G18-E18 | J18: =I18/E18 | X18: 7 | Y18: 7 | Z18: =VLOOKUP(Y18,$C$14:$D$49,2,FALSE) | AA18: =SUMIF(PrilimTable!$N$4:$N$82,X18,PrilimTable!$Q$4:$Q$82) | AB18: =AA18/$E$49 | AC18: =SUMIF(PrilimTable!$O$4:$O$82,Y18,PrilimTable!$S$4:$S$82) | AD18: =AC18/$G$49 | AE18: =AC18-AA18 | AF18: =AE18/AA18 | AG18: 400 | AX18: PathImpedance_TransitCommuterRailInVehicleTimeWeight = 0.65
A19: =VLOOKUP($C19,PrilimTable!$O:$U,7,FALSE) | B19: 8 | C19: =B19 | D19: =VLOOKUP($C19,PrilimTable!$O:$T,2,FALSE) | E19: =SUMIF(PrilimTable!$N$4:$N$82,B19,PrilimTable!$Q$4:$Q$82) | F19: =E19/$E$49 | G19: =SUMIF(PrilimTable!$O$4:$O$82,C19,PrilimTable!$S$4:$S$82) | H19: =G19/$G$49 | I19: =G19-E19 | J19: =I19/E19 | X19: 8 | Y19: 8 | Z19: =VLOOKUP(Y19,$C$14:$D$49,2,FALSE) | AA19: =SUMIF(PrilimTable!$N$4:$N$82,X19,PrilimTable!$Q$4:$Q$82) | AB19: =AA19/$E$49 | AC19: =SUMIF(PrilimTable!$O$4:$O$82,Y19,PrilimTable!$S$4:$S$82) | AD19: =AC19/$G$49 | AE19: =AC19-AA19 | AF19: =AE19/AA19 | AG19: 500 | AX19: PathImpedance_TransitFerryInVehicleTimeWeight = 0.80
A20: =VLOOKUP($C20,PrilimTable!$O:$U,7,FALSE) | B20: 9 | C20: =B20 | D20: =VLOOKUP($C20,PrilimTable!$O:$T,2,FALSE) | E20: =SUMIF(PrilimTable!$N$4:$N$82,B20,PrilimTable!$Q$4:$Q$82) | F20: =E20/$E$49 | G20: =SUMIF(PrilimTable!$O$4:$O$82,C20,PrilimTable!$S$4:$S$82) | H20: =G20/$G$49 | I20: =G20-E20 | J20: =I20/E20 | X20: 9 | Y20: 9 | Z20: =VLOOKUP(Y20,$C$14:$D$49,2,FALSE) | AA20: =SUMIF(PrilimTable!$N$4:$N$82,X20,PrilimTable!$Q$4:$Q$82) | AB20: =AA20/$E$49 | AC20: =SUMIF(PrilimTable!$O$4:$O$82,Y20,PrilimTable!$S$4:$S$82) | AD20: =AC20/$G$49 | AE20: =AC20-AA20 | AF20: =AE20/AA20 | AG20: 600
A21: =VLOOKUP($C21,PrilimTable!$O:$U,7,FALSE) | B21: 14 | C21: =B21 | D21: =VLOOKUP($C21,PrilimTable!$O:$T,2,FALSE) | E21: =SUMIF(PrilimTable!$N$4:$N$82,B21,PrilimTable!$Q$4:$Q$82) | F21: =E21/$E$49 | G21: =SUMIF(PrilimTable!$O$4:$O$82,C21,PrilimTable!$S$4:$S$82) | H21: =G21/$G$49 | I21: =G21-E21 | J21: =I21/E21 | X21: 14 | Y21: 14 | Z21: =VLOOKUP(Y21,$C$14:$D$49,2,FALSE) | AA21: =SUMIF(PrilimTable!$N$4:$N$82,X21,PrilimTable!$Q$4:$Q$82) | AB21: =AA21/$E$49 | AC21: =SUMIF(PrilimTable!$O$4:$O$82,Y21,PrilimTable!$S$4:$S$82) | AD21: =AC21/$G$49 | AE21: =AC21-AA21 | AF21: =AE21/AA21 | AG21: 700
A22: =VLOOKUP($C22,PrilimTable!$O:$U,7,FALSE) | B22: 17 | C22: =B22 | D22: =VLOOKUP($C22,PrilimTable!$O:$T,2,FALSE) | E22: =SUMIF(PrilimTable!$N$4:$N$82,B22,PrilimTable!$Q$4:$Q$82) | F22: =E22/$E$49 | G22: =SUMIF(PrilimTable!$O$4:$O$82,C22,PrilimTable!$S$4:$S$82) | H22: =G22/$G$49 | I22: =G22-E22 | J22: =I22/E22 | X22: 17 | Y22: 17 | Z22: =VLOOKUP(Y22,$C$14:$D$49,2,FALSE) | AA22: =SUMIF(PrilimTable!$N$4:$N$82,X22,PrilimTable!$Q$4:$Q$82) | AB22: =AA22/$E$49 | AC22: =SUMIF(PrilimTable!$O$4:$O$82,Y22,PrilimTable!$S$4:$S$82) | AD22: =AC22/$G$49 | AE22: =AC22-AA22 | AF22: =AE22/AA22 | AG22: 800
A23: =VLOOKUP($C23,PrilimTable!$O:$U,7,FALSE) | B23: 18 | C23: =B23 | D23: =VLOOKUP($C23,PrilimTable!$O:$T,2,FALSE) | E23: =SUMIF(PrilimTable!$N$4:$N$82,B23,PrilimTable!$Q$4:$Q$82) | F23: =E23/$E$49 | G23: =SUMIF(PrilimTable!$O$4:$O$82,C23,PrilimTable!$S$4:$S$82) | H23: =G23/$G$49 | I23: =G23-E23 | J23: =I23/E23 | X23: 18 | Y23: 18 | Z23: =VLOOKUP(Y23,$C$14:$D$49,2,FALSE) | AA23: =SUMIF(PrilimTable!$N$4:$N$82,X23,PrilimTable!$Q$4:$Q$82) | AB23: =AA23/$E$49 | AC23: =SUMIF(PrilimTable!$O$4:$O$82,Y23,PrilimTable!$S$4:$S$82) | AD23: =AC23/$G$49 | AE23: =AC23-AA23 | AF23: =AE23/AA23 | AG23: 900
A24: =VLOOKUP($C24,PrilimTable!$O:$U,7,FALSE) | B24: 19 | C24: =B24 | D24: =VLOOKUP($C24,PrilimTable!$O:$T,2,FALSE) | E24: =SUMIF(PrilimTable!$N$4:$N$82,B24,PrilimTable!$Q$4:$Q$82) | F24: =E24/$E$49 | G24: =SUMIF(PrilimTable!$O$4:$O$82,C24,PrilimTable!$S$4:$S$82) | H24: =G24/$G$49 | I24: =G24-E24 | J24: =I24/E24 | X24: 19 | Y24: 19 | Z24: =VLOOKUP(Y24,$C$14:$D$49,2,FALSE) | AA24: =SUMIF(PrilimTable!$N$4:$N$82,X24,PrilimTable!$Q$4:$Q$82) | AB24: =AA24/$E$49 | AC24: =SUMIF(PrilimTable!$O$4:$O$82,Y24,PrilimTable!$S$4:$S$82) | AD24: =AC24/$G$49 | AE24: =AC24-AA24 | AF24: =AE24/AA24 | AG24: 1000
A25: =VLOOKUP($C25,PrilimTable!$O:$U,7,FALSE) | B25: 22 | C25: =B25 | D25: =VLOOKUP($C25,PrilimTable!$O:$T,2,FALSE) | E25: =SUMIF(PrilimTable!$N$4:$N$82,B25,PrilimTable!$Q$4:$Q$82) | F25: =E25/$E$49 | G25: =SUMIF(PrilimTable!$O$4:$O$82,C25,PrilimTable!$S$4:$S$82) | H25: =G25/$G$49 | I25: =G25-E25 | J25: =I25/E25 | X25: 22 | Y25: 22 | Z25: =VLOOKUP(Y25,$C$14:$D$49,2,FALSE) | AA25: =SUMIF(PrilimTable!$N$4:$N$82,X25,PrilimTable!$Q$4:$Q$82) | AB25: =AA25/$E$49 | AC25: =SUMIF(PrilimTable!$O$4:$O$82,Y25,PrilimTable!$S$4:$S$82) | AD25: =AC25/$G$49 | AE25: =AC25-AA25 | AF25: =AE25/AA25 | AG25: 1100
A26: =VLOOKUP($C26,PrilimTable!$O:$U,7,FALSE) | B26: 23 | C26: =B26 | D26: =VLOOKUP($C26,PrilimTable!$O:$T,2,FALSE) | E26: =SUMIF(PrilimTable!$N$4:$N$82,B26,PrilimTable!$Q$4:$Q$82) | F26: =E26/$E$49 | G26: =SUMIF(PrilimTable!$O$4:$O$82,C26,PrilimTable!$S$4:$S$82) | H26: =G26/$G$49 | I26: =G26-E26 | J26: =I26/E26 | X26: 23 | Y26: 23 | Z26: =VLOOKUP(Y26,$C$14:$D$49,2,FALSE) | AA26: =SUMIF(PrilimTable!$N$4:$N$82,X26,PrilimTable!$Q$4:$Q$82) | AB26: =AA26/$E$49 | AC26: =SUMIF(PrilimTable!$O$4:$O$82,Y26,PrilimTable!$S$4:$S$82) | AD26: =AC26/$G$49 | AE26: =AC26-AA26 | AF26: =AE26/AA26 | AG26: 1200
A27: =VLOOKUP($C27,PrilimTable!$O:$U,7,FALSE) | B27: 28 | C27: =B27 | D27: =VLOOKUP($C27,PrilimTable!$O:$T,2,FALSE) | E27: =SUMIF(PrilimTable!$N$4:$N$82,B27,PrilimTable!$Q$4:$Q$82) | F27: =E27/$E$49 | G27: =SUMIF(PrilimTable!$O$4:$O$82,C27,PrilimTable!$S$4:$S$82) | H27: =G27/$G$49 | I27: =G27-E27 | J27: =I27/E27 | X27: 28 | Y27: 28 | Z27: =VLOOKUP(Y27,$C$14:$D$49,2,FALSE) | AA27: =SUMIF(PrilimTable!$N$4:$N$82,X27,PrilimTable!$Q$4:$Q$82) | AB27: =AA27/$E$49 | AC27: =SUMIF(PrilimTable!$O$4:$O$82,Y27,PrilimTable!$S$4:$S$82) | AD27: =AC27/$G$49 | AE27: =AC27-AA27 | AF27: =AE27/AA27 | AG27: 1300
A28: =VLOOKUP($C28,PrilimTable!$O:$U,7,FALSE) | B28: 29 | C28: =B28 | D28: =VLOOKUP($C28,PrilimTable!$O:$T,2,FALSE) | E28: =SUMIF(PrilimTable!$N$4:$N$82,B28,PrilimTable!$Q$4:$Q$82) | F28: =E28/$E$49 | G28: =SUMIF(PrilimTable!$O$4:$O$82,C28,PrilimTable!$S$4:$S$82) | H28: =G28/$G$49 | I28: =G28-E28 | J28: =I28/E28 | X28: 29 | Y28: 29 | Z28: =VLOOKUP(Y28,$C$14:$D$49,2,FALSE) | AA28: =SUMIF(PrilimTable!$N$4:$N$82,X28,PrilimTable!$Q$4:$Q$82) | AB28: =AA28/$E$49 | AC28: =SUMIF(PrilimTable!$O$4:$O$82,Y28,PrilimTable!$S$4:$S$82) | AD28: =AC28/$G$49 | AE28: =AC28-AA28 | AF28: =AE28/AA28 | AG28: 1400
A29: =VLOOKUP($C29,PrilimTable!$O:$U,7,FALSE) | B29: 34 | C29: =B29 | D29: =VLOOKUP($C29,PrilimTable!$O:$T,2,FALSE) | E29: =SUMIF(PrilimTable!$N$4:$N$82,B29,PrilimTable!$Q$4:$Q$82) | F29: =E29/$E$49 | G29: =SUMIF(PrilimTable!$O$4:$O$82,C29,PrilimTable!$S$4:$S$82) | H29: =G29/$G$49 | I29: =G29-E29 | J29: =I29/E29 | X29: 34 | Y29: 34 | Z29: =VLOOKUP(Y29,$C$14:$D$49,2,FALSE) | AA29: =SUMIF(PrilimTable!$N$4:$N$82,X29,PrilimTable!$Q$4:$Q$82) | AB29: =AA29/$E$49 | AC29: =SUMIF(PrilimTable!$O$4:$O$82,Y29,PrilimTable!$S$4:$S$82) | AD29: =AC29/$G$49 | AE29: =AC29-AA29 | AF29: =AE29/AA29 | AG29: 1500
A30: =VLOOKUP($C30,PrilimTable!$O:$U,7,FALSE) | B30: 41 | C30: =B30 | D30: =VLOOKUP($C30,PrilimTable!$O:$T,2,FALSE) | E30: =SUMIF(PrilimTable!$N$4:$N$82,B30,PrilimTable!$Q$4:$Q$82) | F30: =E30/$E$49 | G30: =SUMIF(PrilimTable!$O$4:$O$82,C30,PrilimTable!$S$4:$S$82) | H30: =G30/$G$49 | I30: =G30-E30 | J30: =I30/E30 | X30: 41 | Y30: 41 | Z30: =VLOOKUP(Y30,$C$14:$D$49,2,FALSE) | AA30: =SUMIF(PrilimTable!$N$4:$N$82,X30,PrilimTable!$Q$4:$Q$82) | AB30: =AA30/$E$49 | AC30: =SUMIF(PrilimTable!$O$4:$O$82,Y30,PrilimTable!$S$4:$S$82) | AD30: =AC30/$G$49 | AE30: =AC30-AA30 | AF30: =AE30/AA30 | AG30: 1600
A31: =VLOOKUP($C31,PrilimTable!$O:$U,7,FALSE) | B31: 42 | C31: =B31 | D31: =VLOOKUP($C31,PrilimTable!$O:$T,2,FALSE) | E31: =SUMIF(PrilimTable!$N$4:$N$82,B31,PrilimTable!$Q$4:$Q$82) | F31: =E31/$E$49 | G31: =SUMIF(PrilimTable!$O$4:$O$82,C31,PrilimTable!$S$4:$S$82) | H31: =G31/$G$49 | I31: =G31-E31 | J31: =I31/E31 | X31: 42 | Y31: 42 | Z31: =VLOOKUP(Y31,$C$14:$D$49,2,FALSE) | AA31: =SUMIF(PrilimTable!$N$4:$N$82,X31,PrilimTable!$Q$4:$Q$82) | AB31: =AA31/$E$49 | AC31: =SUMIF(PrilimTable!$O$4:$O$82,Y31,PrilimTable!$S$4:$S$82) | AD31: =AC31/$G$49 | AE31: =AC31-AA31 | AF31: =AE31/AA31 | AG31: 1700
... A48: =VLOOKUP($C48,PrilimTable!$O:$U,7,FALSE) | B48: 95 | C48: =B48 | D48: =VLOOKUP($C48,PrilimTable!$O:$T,2,FALSE) | E48: =SUMIF(PrilimTable!$N$4:$N$82,B48,PrilimTable!$Q$4:$Q$82) | F48: =E48/$E$49 | G48: =SUMIF(PrilimTable!$O$4:$O$82,C48,PrilimTable!$S$4:$S$82) | H48: =G48/$G$49 | I48: =G48-E48 | J48: =I48/E48 | X48: 95 | Y48: 95 | Z48: =VLOOKUP(Y48,$C$14:$D$49,2,FALSE) | AA48: =SUMIF(PrilimTable!$N$4:$N$82,X48,PrilimTable!$Q$4:$Q$82) | AB48: =AA48/$E$49 | AC48: =SUMIF(PrilimTable!$O$4:$O$82,Y48,PrilimTable!$S$4:$S$82) | AD48: =AC48/$G$49 | AE48: =AC48-AA48 | AF48: =AE48/AA48 | AG48: 3400
D49: TOTAL | E49: =SUM(E15:E48) | F49: =SUM(F15:F48) | G49: =SUM(G15:G48) | H49: =SUM(H15:H48) | I49: =G49-E49 | J49: =I49/E49 | AA49: =SUM(AA15:AA48) | AB49: 0.998 | AC49: =SUM(AC15:AC48) | AD49: 1 | AE49: =AC49-AA49 | AF49: =AE49/AA49

Sheet PrilimTable
Q2: OBS | S2: ABM_12132015
B3: ROUTE_STATION_NUM | C3: Boardings | M3: Mode | N3: Rte Id (OBS) | O3: Rte Id (ABM) | P3: Rte Name | Q3: Boardings | R3: Percentage | S3: Boardings | T3: Percentage | U3: Mode
B4: 3 | C4: =VLOOKUP($B4,Aggregated_Transit_Final_V2!$B:$H,7,FALSE) | M4: =VLOOKUP($O4,ABM_RteName!$A:$D,4,FALSE) | N4: 3 | O4: 3 | P4: =VLOOKUP($O4,ABM_RteName!$A:$C,3,FALSE) | Q4: =VLOOKUP(N4,$B:$C,2,FALSE) | R4: =Q4/$Q$38 | S4: =SUMIF(BoardingByRoute_ABM!$B:$B,O4,BoardingByRoute_ABM!$N:$N) | T4: =S4/S$38 | U4: =VLOOKUP($O4,ABM_RteName!$A:$D,4,FALSE)
B5: 4 | C5: =VLOOKUP($B5,Aggregated_Transit_Final_V2!$B:$H,7,FALSE) | M5: =VLOOKUP($O5,ABM_RteName!$A:$D,4,FALSE) | N5: 4 | O5: 4 | P5: =VLOOKUP($O5,ABM_RteName!$A:$C,3,FALSE) | Q5: =VLOOKUP(N5,$B:$C,2,FALSE) | R5: =Q5/$Q$38 | S5: =SUMIF(BoardingByRoute_ABM!$B:$B,O5,BoardingByRoute_ABM!$N:$N) | T5: =S5/S$38 | U5: =VLOOKUP($O5,ABM_RteName!$A:$D,4,FALSE)
B6: 6 | C6: =VLOOKUP($B6,Aggregated_Transit_Final_V2!$B:$H,7,FALSE) | M6: =VLOOKUP($O6,ABM_RteName!$A:$D,4,FALSE) | N6: 6 | O6: 6 | P6: =VLOOKUP($O6,ABM_RteName!$A:$C,3,FALSE) | Q6: =VLOOKUP(N6,$B:$C,2,FALSE) | R6: =Q6/$Q$38 | S6: =SUMIF(BoardingByRoute_ABM!$B:$B,O6,BoardingByRoute_ABM!$N:$N) | T6: =S6/S$38 | U6: =VLOOKUP($O6,ABM_RteName!$A:$D,4,FALSE)
B7: 7 | C7: =VLOOKUP($B7,Aggregated_Transit_Final_V2!$B:$H,7,FALSE) | M7: =VLOOKUP($O7,ABM_RteName!$A:$D,4,FALSE) | N7: 7 | O7: 7 | P7: =VLOOKUP($O7,ABM_RteName!$A:$C,3,FALSE) | Q7: =VLOOKUP(N7,$B:$C,2,FALSE) | R7: =Q7/$Q$38 | S7: =SUMIF(BoardingByRoute_ABM!$B:$B,O7,BoardingByRoute_ABM!$N:$N) | T7: =S7/S$38 | U7: =VLOOKUP($O7,ABM_RteName!$A:$D,4,FALSE)
B8: 8 | C8: =VLOOKUP($B8,Aggregated_Transit_Final_V2!$B:$H,7,FALSE) | M8: =VLOOKUP($O8,ABM_RteName!$A:$D,4,FALSE) | N8: 8 | O8: 8 | P8: =VLOOKUP($O8,ABM_RteName!$A:$C,3,FALSE) | Q8: =VLOOKUP(N8,$B:$C,2,FALSE) | R8: =Q8/$Q$38 | S8: =SUMIF(BoardingByRoute_ABM!$B:$B,O8,BoardingByRoute_ABM!$N:$N) | T8: =S8/S$38 | U8: =VLOOKUP($O8,ABM_RteName!$A:$D,4,FALSE)
B9: 9 | C9: =VLOOKUP($B9,Aggregated_Transit_Final_V2!$B:$H,7,FALSE) | M9: =VLOOKUP($O9,ABM_RteName!$A:$D,4,FALSE) | N9: 9 | O9: 9 | P9: =VLOOKUP($O9,ABM_RteName!$A:$C,3,FALSE) | Q9: =VLOOKUP(N9,$B:$C,2,FALSE) | R9: =Q9/$Q$38 | S9: =SUMIF(BoardingByRoute_ABM!$B:$B,O9,BoardingByRoute_ABM!$N:$N) | T9: =S9/S$38 | U9: =VLOOKUP($O9,ABM_RteName!$A:$D,4,FALSE)
B10: 14 | C10: =VLOOKUP($B10,Aggregated_Transit_Final_V2!$B:$H,7,FALSE) | M10: =VLOOKUP($O10,ABM_RteName!$A:$D,4,FALSE) | N10: 14 | O10: 14 | P10: =VLOOKUP($O10,ABM_RteName!$A:$C,3,FALSE) | Q10: =VLOOKUP(N10,$B:$C,2,FALSE) | R10: =Q10/$Q$38 | S10: =SUMIF(BoardingByRoute_ABM!$B:$B,O10,BoardingByRoute_ABM!$N:$N) | T10: =S10/S$38 | U10: =VLOOKUP($O10,ABM_RteName!$A:$D,4,FALSE)
B11: 17 | C11: =VLOOKUP($B11,Aggregated_Transit_Final_V2!$B:$H,7,FALSE) | M11: =VLOOKUP($O11,ABM_RteName!$A:$D,4,FALSE) | N11: 17 | O11: 17 | P11: =VLOOKUP($O11,ABM_RteName!$A:$C,3,FALSE) | Q11: =VLOOKUP(N11,$B:$C,2,FALSE) | R11: =Q11/$Q$38 | S11: =SUMIF(BoardingByRoute_ABM!$B:$B,O11,BoardingByRoute_ABM!$N:$N) | T11: =S11/S$38 | U11: =VLOOKUP($O11,ABM_RteName!$A:$D,4,FALSE)
B12: 18 | C12: =VLOOKUP($B12,Aggregated_Transit_Final_V2!$B:$H,7,FALSE) | M12: =VLOOKUP($O12,ABM_RteName!$A:$D,4,FALSE) | N12: 18 | O12: 18 | P12: =VLOOKUP($O12,ABM_RteName!$A:$C,3,FALSE) | Q12: =VLOOKUP(N12,$B:$C,2,FALSE) | R12: =Q12/$Q$38 | S12: =SUMIF(BoardingByRoute_ABM!$B:$B,O12,BoardingByRoute_ABM!$N:$N) | T12: =S12/S$38 | U12: =VLOOKUP($O12,ABM_RteName!$A:$D,4,FALSE)
B13: 19 | C13: =VLOOKUP($B13,Aggregated_Transit_Final_V2!$B:$H,7,FALSE) | M13: =VLOOKUP($O13,ABM_RteName!$A:$D,4,FALSE) | N13: 19 | O13: 19 | P13: =VLOOKUP($O13,ABM_RteName!$A:$C,3,FALSE) | Q13: =VLOOKUP(N13,$B:$C,2,FALSE) | R13: =Q13/$Q$38 | S13: =SUMIF(BoardingByRoute_ABM!$B:$B,O13,BoardingByRoute_ABM!$N:$N) | T13: =S13/S$38 | U13: =VLOOKUP($O13,ABM_RteName!$A:$D,4,FALSE)
B14: 22 | C14: =VLOOKUP($B14,Aggregated_Transit_Final_V2!$B:$H,7,FALSE) | M14: =VLOOKUP($O14,ABM_RteName!$A:$D,4,FALSE) | N14: 22 | O14: 22 | P14: =VLOOKUP($O14,ABM_RteName!$A:$C,3,FALSE) | Q14: =VLOOKUP(N14,$B:$C,2,FALSE) | R14: =Q14/$Q$38 | S14: =SUMIF(BoardingByRoute_ABM!$B:$B,O14,BoardingByRoute_ABM!$N:$N) | T14: =S14/S$38 | U14: =VLOOKUP($O14,ABM_RteName!$A:$D,4,FALSE)
B15: 23 | C15: =VLOOKUP($B15,Aggregated_Transit_Final_V2!$B:$H,7,FALSE) | M15: =VLOOKUP($O15,ABM_RteName!$A:$D,4,FALSE) | N15: 23 | O15: 23 | P15: =VLOOKUP($O15,ABM_RteName!$A:$C,3,FALSE) | Q15: =VLOOKUP(N15,$B:$C,2,FALSE) | R15: =Q15/$Q$38 | S15: =SUMIF(BoardingByRoute_ABM!$B:$B,O15,BoardingByRoute_ABM!$N:$N) | T15: =S15/S$38 | U15: =VLOOKUP($O15,ABM_RteName!$A:$D,4,FALSE)
... B37: 95 | C37: =VLOOKUP($B37,Aggregated_Transit_Final_V2!$B:$H,7,FALSE) | M37: =VLOOKUP($O37,ABM_RteName!$A:$D,4,FALSE) | N37: 95 | O37: 95 | P37: =VLOOKUP($O37,ABM_RteName!$A:$C,3,FALSE) | Q37: =VLOOKUP(N37,$B:$C,2,FALSE) | R37: =Q37/$Q$38 | S37: =SUMIF(BoardingByRoute_ABM!$B:$B,O37,BoardingByRoute_ABM!$N:$N) | T37: =S37/S$38 | U37: =VLOOKUP($O37,ABM_RteName!$A:$D,4,FALSE)
N38: TOTAL | Q38: =SUM(Q4:Q37) | R38: =SUM(R4:R37) | S38: =SUM(S4:S37) | T38: =SUM(T4:T37)
P44: Following stations are replaced with '301'
P45: DON | Q45: 301
P46: HER | Q46: 301
P47: JUL | Q47: 301
P48: LEB | Q48: 301
P49: MAR | Q49: 301
P50: RIV | Q50: 301
P51: 18X | Q51: 18
A54: Boardings by transit sub-mode
C55: OBS | E55: ABM | G55: Sub-mode Constant (DaySim)
B56: Transit sub-mode | C56: Count | D56: Percentage | E56: Count | F56: Percentage | G56: Utils | H56: Mins
B57: Local Bus | C57: =25297-BoardingByRoute_All!E48 | D57: =C57/$C$61 | E57: =IF(ISNUMBER(TrnStat.asc!J26),TrnStat.asc!J26,CONCATENATE(LEFT(TrnStat.asc!J26,2),RIGHT(TrnStat.asc!J26,3))) | F57: =E57/E$61 | G57: -0.1 | H57: =G57/0.03
B58: Express Bus | C58: 2122 | D58: =C58/$C$61 | E58: =IF(ISNUMBER(TrnStat.asc!K27),TrnStat.asc!K27,CONCATENATE(LEFT(TrnStat.asc!K27,2),RIGHT(TrnStat.asc!K27,3)))+IF(ISNUMBER(TrnStat.asc!K28),TrnStat.asc!K28,CONCATENATE(LEFT(TrnStat.asc!K28,2),RIGHT(TrnStat.asc!K28,3))) | F58: =E58/E$61 | G58: 0.45 | H58: =G58/0.03
B59: BRT | C59: 2660 | D59: =C59/$C$61 | E59: =IF(ISNUMBER(TrnStat.asc!K29),TrnStat.asc!K29,CONCATENATE(LEFT(TrnStat.asc!K29,2),RIGHT(TrnStat.asc!K29,3))) | F59: =E59/E$61 | G59: -0.1 | H59: =G59/0.03
B60: Commuter Rail | C60: =1243+BoardingByRoute_All!E48 | D60: =C60/$C$61 | E60: =IF(ISNUMBER(TrnStat.asc!J30),TrnStat.asc!J30,CONCATENATE(LEFT(TrnStat.asc!J30,2),RIGHT(TrnStat.asc!J30,3)))+IF(ISNUMBER(TrnStat.asc!J31),TrnStat.asc!J31,CONCATENATE(LEFT(TrnStat.asc!J31,2),RIGHT(TrnStat.asc!J31,3))) | F60: =E60/E$61 | G60: 1.3 | H60: =G60/0.03
B61: Total | C61: 31322 | D61: =C61/$C$61 | E61: =SUM(E57:E60) | F61: 1
B63: Transfer Rate | C63: 0.596 | E63: =-(TrnStat.asc!D46)

Sheet Aggregated_Transit_Final_V2
A1: RouteNumChar | B1: RouteNumNum | C1: RouteObs | D1: ON | E1: ObsName | F1: ObsOn | G1: ObsOff | H1: boarding
A2: 3 | B2: 3 | H2: =IFERROR(VLOOKUP(B2,Obs_Ridership!$A:$G,7,FALSE),"")
A3: 4 | B3: 4 | H3: =IFERROR(VLOOKUP(B3,Obs_Ridership!$A:$G,7,FALSE),"")
A4: 6 | B4: 6 | H4: =IFERROR(VLOOKUP(B4,Obs_Ridership!$A:$G,7,FALSE),"")
A5: 7 | B5: 7 | H5: =IFERROR(VLOOKUP(B5,Obs_Ridership!$A:$G,7,FALSE),"")
A6: 8 | B6: 8 | H6: =IFERROR(VLOOKUP(B6,Obs_Ridership!$A:$G,7,FALSE),"")
A7: 9 | B7: 9 | H7: =IFERROR(VLOOKUP(B7,Obs_Ridership!$A:$G,7,FALSE),"")
A8: 14 | B8: 14 | H8: =IFERROR(VLOOKUP(B8,Obs_Ridership!$A:$G,7,FALSE),"")
A9: 17 | B9: 17 | H9: =IFERROR(VLOOKUP(B9,Obs_Ridership!$A:$G,7,FALSE),"")
A10: 18 | B10: 18 | H10: =IFERROR(VLOOKUP(B10,Obs_Ridership!$A:$G,7,FALSE),"")
A11: 19 | B11: 19 | H11: =IFERROR(VLOOKUP(B11,Obs_Ridership!$A:$G,7,FALSE),"")
A12: 22 | B12: 22 | H12: =IFERROR(VLOOKUP(B12,Obs_Ridership!$A:$G,7,FALSE),"")
A13: 23 | B13: 23 | H13: =IFERROR(VLOOKUP(B13,Obs_Ridership!$A:$G,7,FALSE),"")
... A29: 84 | B29: 84 | H29: =IFERROR(VLOOKUP(B29,Obs_Ridership!$A:$G,7,FALSE),"")
A30: 86 | B30: 86 | H30: =IFERROR(VLOOKUP(B30,Obs_Ridership!$A:$G,7,FALSE),"") | I30: "RouteNumNum" isn't correct, used "RouteNumChar"
A31: 87 | B31: 87 | H31: =IFERROR(VLOOKUP(B31,Obs_Ridership!$A:$G,7,FALSE),"")
A32: 89 | B32: 89 | H32: =IFERROR(VLOOKUP(B32,Obs_Ridership!$A:$G,7,FALSE),"")
A33: 90 | B33: 90 | H33: =IFERROR(VLOOKUP(B33,Obs_Ridership!$A:$G,7,FALSE),"")
A34: 93 | B34: 93 | H34: =IFERROR(VLOOKUP(B34,Obs_Ridership!$A:$G,7,FALSE),"")
A35: 95 | B35: 95 | H35: =IFERROR(VLOOKUP(B35,Obs_Ridership!$A:$G,7,FALSE),"")

Sheet TrnStat.asc
B2: Created | C2: On: | D2: Sat, | E2: May | F2: 11 | G2: 2024 | H2: (20:40:06)
B3: Nashville | C3: Transit | D3: Assignment | E3: Summary
B5: Alternative:
A9: TRIPS | B9: BY | C9: TOD | D9: AND | E9: MODE | F9: (MODE | G9: CHOICE | H9: MODEL | I9: RESULTS)
A10: |
B11: Per | C11: DriveAlo | D11: ShrRide | E11: 2 | F11: ShrRide | G11: 3+ | H11: WalkLocal | I11: WalkBrt | J11: WalkExpBus | K11: WalkUrbRail | L11: WalkComRail | M11: PnRLocal | N11: PnRBrt | O11: PnRExpBus | P11: PnRUrbRail | Q11: PnRComRail | R11: KnRLocal | S11: KnRBrt | T11: KnRExpBus | U11: KnRUrbRail | V11: KnrComRail | W11: | | X11: Total | Y11: Trips
A12: |
B13: AM | C13: -- | D13: -- | E13: -- | F13: 4433 | G13: 181 | H13: 13 | I13: 0 | J13: 604 | K13: 750 | L13: 0 | M13: 1 | N13: 0 | O13: 576 | P13: 0 | Q13: 0 | R13: 0 | S13: 0 | T13: 0 | U13: | | V13: --
B14: MD | C14: -- | D14: -- | E14: -- | F14: 10864 | G14: 252 | H14: 30 | I14: 0 | J14: 0 | K14: 444 | L14: 0 | M14: 1 | N14: 0 | O14: 0 | P14: 0 | Q14: 0 | R14: 0 | S14: 0 | T14: 0 | U14: | | V14: --
B15: PM | C15: -- | D15: -- | E15: -- | F15: 6643 | G15: 236 | H15: 21 | I15: 0 | J15: 1757 | K15: 835 | L15: 0 | M15: 1 | N15: 0 | O15: 432 | P15: 0 | Q15: 0 | R15: 0 | S15: 0 | T15: 0 | U15: | | V15: --
B16: OP | C16: -- | D16: -- | E16: -- | F16: 2511 | G16: 52 | H16: 1 | I16: 0 | J16: 0 | K16: 127 | L16: 0 | M16: 1 | N16: 0 | O16: 0 | P16: 0 | Q16: 0 | R16: 0 | S16: 0 | T16: 0 | U16: | | V16: --
A17: |
A18: TOTAL | B18: -- | C18: -- | D18: -- | E18: 24451 | F18: 721 | G18: 65 | H18: 0 | I18: 2361 | J18: 2156 | K18: 0 | L18: 4 | M18: 0 | N18: 1008 | O18: 0 | P18: 0 | Q18: 0 | R18: 0 | S18: 0 | T18: | | U18: --
A22: TRANSIT | B22: BOARDINGS | C22: BY | D22: MODE | E22: (TRANSIT | F22: ASSIGNMENT | G22: RESULTS)
A23: |
B24: Mode | C24: Mode | D24: Name | E24: Dwell | F24: Factor | G24: AM | H24: MD | I24: PM | J24: OP | K24: | | L24: Total
A25: |
B26: 1 | C26: Local | D26: 2 | E26: 9743 | F26: 17852 | G26: 14053 | H26: 3872 | I26: | | J26: 45527
B27: 6 | C27: Express | D27: Bus | E27: 1 | F27: 13 | G27: 31 | H27: 20 | I27: 1 | J27: | | K27: 65
B28: 7 | C28: Commuter | D28: Bus | E28: 1 | F28: 1 | G28: 0 | H28: 2 | I28: 0 | J28: | | K28: 3
B29: 8 | C29: Existing | D29: BRT | E29: 1.5 | F29: 176 | G29: 230 | H29: 235 | I29: 50 | J29: | | K29: 689
B30: 11 | C30: Shuttle | D30: 2 | E30: 548 | F30: 0 | G30: 1704 | H30: 0 | I30: | | J30: 2253
B31: 12 | C31: ComRail | D31: 0.5 | E31: 139 | F31: 0 | G31: 112 | H31: 0 | I31: | | J31: 253
A32: |
B33: TOTAL | C33: 10619 | D33: 18113 | E33: 16125 | F33: 3922 | G33: | | H33: 48790
A37: TRANSFER | B37: RATES | C37: BY | D37: TOD
B39: Period | C39: Transfers | D39: (Rate)
B41: AM | C41: 4061 | D41: (61.93%)
B42: MD | C42: 6522 | D42: (56.27%)
B43: PM | C43: 6200 | D43: (62.47%)
B44: OP | C44: 1230 | D44: (45.70%)
B46: TOTAL | C46: 18024 | D46: (58.58%)
A50: TRANSIT | B50: BOARDINGS | C50: BY | D50: ROUTE | E50: (TRANSIT | F50: ASSIGNMENT | G50: RESULTS)
A51: |
B52: Route | C52: Mode | D52: Route | E52: Name | F52: AM | G52: MD | H52: PM | I52: OP | J52: | | K52: Total
A53: |
B54: 3 | C54: 1 | D54: Rte | E54: 3 | F54: 932 | G54: 1550 | H54: 1345 | I54: 347 | J54: | | K54: 4175
B55: 4 | C55: 1 | D55: Rte | E55: 4 | F55: 208 | G55: 384 | H55: 269 | I55: 52 | J55: | | K55: 913
B56: 6 | C56: 1 | D56: Rte | E56: 6 | F56: 179 | G56: 71 | H56: 247 | I56: 22 | J56: | | K56: 519
B57: 7 | C57: 1 | D57: Rte | E57: 7 | F57: 1875 | G57: 5732 | H57: 2718 | I57: 1181 | J57: | | K57: 11508
...

Sheet Obs_Ridership
A1: Model Rte txt+A36 | B1: Model Rte num | C1: Modelid | D1: Model Rte Name | E1: Ridership Oct 2023 | F1: Daily_20 | G1: Daily_22
A2: 3 | B2: 3 | C2: 35 | D2: Rte 3 West End (Bellevue) IB | E2: 55372 | F2: 2768.6 | G2: 2516.9091
A3: 4 | B3: 4 | C3: 17 | D3: Rte 4 Shelby IB | E3: 20703 | F3: 1035.15 | G3: 941.04545
A4: 6 | B4: 6 | C4: 74 | D4: Rte 6 Lebanon Rd IB | E4: 18000 | F4: 900 | G4: 818.18182
A5: 7 | B5: 7 | C5: 37 | D5: Rte 7 Hillsboro IB | E5: 40515 | F5: 2025.75 | G5: 1841.5909
A6: 8 | B6: 8 | C6: 32 | D6: Rte 8 8TH AVENUE SOUTH iB | E6: 20777 | F6: 1038.85 | G6: 944.40909
A7: 9 | B7: 9 | C7: 51 | D7: Rte 9 MetroCenter IB | E7: 7713 | F7: 385.65 | G7: 350.59091
A8: 14 | B8: 14 | C8: 29 | D8: Rte 14 WHITES CREEK iB | E8: 7352 | F8: 367.6 | G8: 334.18182
A9: 17 | B9: 17 | C9: 2 | D9: Rte 17 12TH AVENUE SOUTH iB | E9: 14035 | F9: 701.75 | G9: 637.95455
A10: 18 | B10: 18 | C10: 78 | D10: Rte 18 Airport Exp IB | E10: 14914 | F10: 745.7 | G10: 677.90909
A11: 19 | B11: 19 | C11: 49 | D11: Rte 19 Herman IB | E11: 21026 | F11: 1051.3 | G11: 955.72727
A12: 22 | B12: 22 | C12: 60 | D12: Rte 22 Bordeaux (Kings Ln) IB | E12: 33119 | F12: 1655.95 | G12: 1505.4091
A13: 23 | B13: 23 | C13: 15 | D13: Rte 23 Dickerson Pike IB | E13: 59191 | F13: 2959.55 | G13: 2690.5
... A35: 95 | B35: 95 | C35: 72 | D35: Rte 95 Spring Hill Exp IB | E35: 1136 | F35: 56.8 | G35: 51.636364
D36: Rover | E36: 9187 | F36: 459.35 | G36: 417.59091
D37: FTA | E37: 12084 | F37: 604.2 | G37: 549.27273
D38: Mule
D40: TOTAL | E40: 778330 | F40: 38916.5 | G40: 35378.636
F41: 38916.5 | G41: check monthly weekday/20
F42: =E40/20

Sheet BoardingByRoute_ABM
B1: Route | C1: Mode | D1: Route Name | F1: AM | G1: MD | H1: PM | I1: OP | | J1: T | K1: otal | M1: text | N1: Boarding
B2: =TrnStat.asc!B54 | C2: =TrnStat.asc!C54 | D2: =TrnStat.asc!D54 | E2: =TrnStat.asc!E54 | F2: =TrnStat.asc!F54 | G2: =TrnStat.asc!G54 | H2: =TrnStat.asc!H54 | I2: =TrnStat.asc!I54 | ... K2: =TrnStat.asc!K54 | M2: =IF(ISNUMBER(K2),K2,CONCATENATE(LEFT(K2,2),RIGHT(K2,3))) | N2: =VALUE(M2)
B3: =TrnStat.asc!B55 | C3: =TrnStat.asc!C55 | D3: =TrnStat.asc!D55 | E3: =TrnStat.asc!E55 | F3: =TrnStat.asc!F55 | G3: =TrnStat.asc!G55 | H3: =TrnStat.asc!H55 | I3: =TrnStat.asc!I55 | ... K3: =TrnStat.asc!K55 | M3: =IF(ISNUMBER(K3),K3,CONCATENATE(LEFT(K3,2),RIGHT(K3,3))) | N3: =VALUE(M3)
B4: =TrnStat.asc!B56 | C4: =TrnStat.asc!C56 | D4: =TrnStat.asc!D56 | E4: =TrnStat.asc!E56 | F4: =TrnStat.asc!F56 | G4: =TrnStat.asc!G56 | H4: =TrnStat.asc!H56 | I4: =TrnStat.asc!I56 | ... K4: =TrnStat.asc!K56 | M4: =IF(ISNUMBER(K4),K4,CONCATENATE(LEFT(K4,2),RIGHT(K4,3))) | N4: =VALUE(M4)
B5: =TrnStat.asc!B57 | C5: =TrnStat.asc!C57 | D5: =TrnStat.asc!D57 | E5: =TrnStat.asc!E57 | F5: =TrnStat.asc!F57 | G5: =TrnStat.asc!G57 | H5: =TrnStat.asc!H57 | I5: =TrnStat.asc!I57 | ... K5: =TrnStat.asc!K57 | M5: =IF(ISNUMBER(K5),K5,CONCATENATE(LEFT(K5,2),RIGHT(K5,3))) | N5: =VALUE(M5)
B6: =TrnStat.asc!B58 | C6: =TrnStat.asc!C58 | D6: =TrnStat.asc!D58 | E6: =TrnStat.asc!E58 | F6: =TrnStat.asc!F58 | G6: =TrnStat.asc!G58 | H6: =TrnStat.asc!H58 | I6: =TrnStat.asc!I58 | ... K6: =TrnStat.asc!K58 | M6: =IF(ISNUMBER(K6),K6,CONCATENATE(LEFT(K6,2),RIGHT(K6,3))) | N6: =VALUE(M6)
B7: =TrnStat.asc!B59 | C7: =TrnStat.asc!C59 | D7: =TrnStat.asc!D59 | E7: =TrnStat.asc!E59 | F7: =TrnStat.asc!F59 | G7: =TrnStat.asc!G59 | H7: =TrnStat.asc!H59 | I7: =TrnStat.asc!I59 | ... K7: =TrnStat.asc!K59 | M7: =IF(ISNUMBER(K7),K7,CONCATENATE(LEFT(K7,2),RIGHT(K7,3))) | N7: =VALUE(M7)
B8: =TrnStat.asc!B60 | C8: =TrnStat.asc!C60 | D8: =TrnStat.asc!D60 | E8: =TrnStat.asc!E60 | F8: =TrnStat.asc!F60 | G8: =TrnStat.asc!G60 | H8: =TrnStat.asc!H60 | I8: =TrnStat.asc!I60 | ... K8: =TrnStat.asc!K60 | M8: =IF(ISNUMBER(K8),K8,CONCATENATE(LEFT(K8,2),RIGHT(K8,3))) | N8: =VALUE(M8)
B9: =TrnStat.asc!B61 | C9: =TrnStat.asc!C61 | D9: =TrnStat.asc!D61 | E9: =TrnStat.asc!E61 | F9: =TrnStat.asc!F61 | G9: =TrnStat.asc!G61 | H9: =TrnStat.asc!H61 | I9: =TrnStat.asc!I61 | ... K9: =TrnStat.asc!K61 | M9: =IF(ISNUMBER(K9),K9,CONCATENATE(LEFT(K9,2),RIGHT(K9,3))) | N9: =VALUE(M9)
B10: =TrnStat.asc!B62 | C10: =TrnStat.asc!C62 | D10: =TrnStat.asc!D62 | E10: =TrnStat.asc!E62 | F10: =TrnStat.asc!F62 | G10: =TrnStat.asc!G62 | H10: =TrnStat.asc!H62 | I10: =TrnStat.asc!I62 | ... K10: =TrnStat.asc!K62 | M10: =IF(ISNUMBER(K10),K10,CONCATENATE(LEFT(K10,2),RIGHT(K10,3))) | N10: =VALUE(M10)
B11: =TrnStat.asc!B63 | C11: =TrnStat.asc!C63 | D11: =TrnStat.asc!D63 | E11: =TrnStat.asc!E63 | F11: =TrnStat.asc!F63 | G11: =TrnStat.asc!G63 | H11: =TrnStat.asc!H63 | I11: =TrnStat.asc!I63 | ... K11: =TrnStat.asc!K63 | M11: =IF(ISNUMBER(K11),K11,CONCATENATE(LEFT(K11,2),RIGHT(K11,3))) | N11: =VALUE(M11)
B12: =TrnStat.asc!B64 | C12: =TrnStat.asc!C64 | D12: =TrnStat.asc!D64 | E12: =TrnStat.asc!E64 | F12: =TrnStat.asc!F64 | G12: =TrnStat.asc!G64 | H12: =TrnStat.asc!H64 | I12: =TrnStat.asc!I64 | ... K12: =TrnStat.asc!K64 | M12: =IF(ISNUMBER(K12),K12,CONCATENATE(LEFT(K12,2),RIGHT(K12,3))) | N12: =VALUE(M12)
B13: =TrnStat.asc!B65 | C13: =TrnStat.asc!C65 | D13: =TrnStat.asc!D65 | E13: =TrnStat.asc!E65 | F13: =TrnStat.asc!F65 | G13: =TrnStat.asc!G65 | H13: =TrnStat.asc!H65 | I13: =TrnStat.asc!I65 | ... K13: =TrnStat.asc!K65 | M13: =IF(ISNUMBER(K13),K13,CONCATENATE(LEFT(K13,2),RIGHT(K13,3))) | N13: =VALUE(M13)
... B52: =TrnStat.asc!B104 | C52: =TrnStat.asc!C104 | D52: =TrnStat.asc!D104 | E52: =TrnStat.asc!E104 | F52: =TrnStat.asc!F104 | G52: =TrnStat.asc!G104 | H52: =TrnStat.asc!H104 | I52: =TrnStat.asc!I104 | ... K52: =TrnStat.asc!K104 | M52: =IF(ISNUMBER(K52),K52,CONCATENATE(LEFT(K52,2),RIGHT(K52,3))) | N52: =VALUE(M52)

Sheet OBS_RteName
A1: Rte ID | B1: Route Name
A2: 3 | B2: Rte 3 West End (Bellevue) IB
A3: 4 | B3: Rte 4 Shelby IB
A4: 6 | B4: Rte 6 Lebanon Rd IB
A5: 7 | B5: Rte 7 Hillsboro IB
A6: 8 | B6: Rte 8 8TH AVENUE SOUTH iB
A7: 9 | B7: Rte 9 MetroCenter IB
A8: 14 | B8: Rte 14 WHITES CREEK iB
A9: 17 | B9: Rte 17 12TH AVENUE SOUTH iB
A10: 18 | B10: Rte 18 Airport Exp IB
A11: 19 | B11: Rte 19 Herman IB
A12: 22 | B12: Rte 22 Bordeaux (Kings Ln) IB
A13: 23 | B13: Rte 23 Dickerson Pike IB
... A35: 95 | B35: Rte 95 Spring Hill Exp IB

Sheet ABM_RteName
A1: Route Id | B1: Route Name (Temp) | C1: Route Name | D1: Mode | E1: Track | J1: RouteNum | K1: Route_Name | L1: modes | M1: Mode | N1: Track
A2: 3 | B2: =VLOOKUP(A2,$J:$M,2,FALSE) | C2: =IF(ISNUMBER(SEARCH("IB",B2)),LEFT(B2,LEN(B2)-3),IF(ISNUMBER(SEARCH("OB",B2)),LEFT(B2,LEN(B2)-3),B2)) | D2: =VLOOKUP($A2,$J:$M,4,FALSE) | E2: =VLOOKUP($A2,$J:$N,5,FALSE) | J2: 3 | K2: Rte 3 West End (White Bridge) IB | L2: 4 | M2: 1 | N2: 55
A3: 4 | B3: =VLOOKUP(A3,$J:$M,2,FALSE) | C3: =IF(ISNUMBER(SEARCH("IB",B3)),LEFT(B3,LEN(B3)-3),IF(ISNUMBER(SEARCH("OB",B3)),LEFT(B3,LEN(B3)-3),B3)) | D3: =VLOOKUP($A3,$J:$M,4,FALSE) | E3: =VLOOKUP($A3,$J:$N,5,FALSE) | J3: 3 | K3: Rte 3 West End (Bellevue) IB | L3: 4 | M3: 1 | N3: 54
A4: 6 | B4: =VLOOKUP(A4,$J:$M,2,FALSE) | C4: =IF(ISNUMBER(SEARCH("IB",B4)),LEFT(B4,LEN(B4)-3),IF(ISNUMBER(SEARCH("OB",B4)),LEFT(B4,LEN(B4)-3),B4)) | D4: =VLOOKUP($A4,$J:$M,4,FALSE) | E4: =VLOOKUP($A4,$J:$N,5,FALSE) | J4: 3 | K4: Rte 3 West End (Bellevue) oB | L4: 4 | M4: 1 | N4: 54
A5: 7 | B5: =VLOOKUP(A5,$J:$M,2,FALSE) | C5: =IF(ISNUMBER(SEARCH("IB",B5)),LEFT(B5,LEN(B5)-3),IF(ISNUMBER(SEARCH("OB",B5)),LEFT(B5,LEN(B5)-3),B5)) | D5: =VLOOKUP($A5,$J:$M,4,FALSE) | E5: =VLOOKUP($A5,$J:$N,5,FALSE) | J5: 3 | K5: Rte 3 West End (White Bridge) OB | L5: 4 | M5: 1 | N5: 55
A6: 8 | B6: =VLOOKUP(A6,$J:$M,2,FALSE) | C6: =IF(ISNUMBER(SEARCH("IB",B6)),LEFT(B6,LEN(B6)-3),IF(ISNUMBER(SEARCH("OB",B6)),LEFT(B6,LEN(B6)-3),B6)) | D6: =VLOOKUP($A6,$J:$M,4,FALSE) | E6: =VLOOKUP($A6,$J:$N,5,FALSE) | J6: 4 | K6: Rte 4 Shelby IB | L6: 4 | M6: 1 | N6: 57
A7: 9 | B7: =VLOOKUP(A7,$J:$M,2,FALSE) | C7: =IF(ISNUMBER(SEARCH("IB",B7)),LEFT(B7,LEN(B7)-3),IF(ISNUMBER(SEARCH("OB",B7)),LEFT(B7,LEN(B7)-3),B7)) | D7: =VLOOKUP($A7,$J:$M,4,FALSE) | E7: =VLOOKUP($A7,$J:$N,5,FALSE) | J7: 4 | K7: Rte 4 Shelby OB | L7: 4 | M7: 1 | N7: 57
A8: 14 | B8: =VLOOKUP(A8,$J:$M,2,FALSE) | C8: =IF(ISNUMBER(SEARCH("IB",B8)),LEFT(B8,LEN(B8)-3),IF(ISNUMBER(SEARCH("OB",B8)),LEFT(B8,LEN(B8)-3),B8)) | D8: =VLOOKUP($A8,$J:$M,4,FALSE) | E8: =VLOOKUP($A8,$J:$N,5,FALSE) | J8: 6 | K8: Rte 6 Lebanon Rd OB | L8: 4 | M8: 1 | N8: 67
A9: 17 | B9: =VLOOKUP(A9,$J:$M,2,FALSE) | C9: =IF(ISNUMBER(SEARCH("IB",B9)),LEFT(B9,LEN(B9)-3),IF(ISNUMBER(SEARCH("OB",B9)),LEFT(B9,LEN(B9)-3),B9)) | D9: =VLOOKUP($A9,$J:$M,4,FALSE) | E9: =VLOOKUP($A9,$J:$N,5,FALSE) | J9: 6 | K9: Rte 6 Lebanon Rd IB | L9: 4 | M9: 1 | N9: 67
A10: 18 | B10: =VLOOKUP(A10,$J:$M,2,FALSE) | C10: =IF(ISNUMBER(SEARCH("IB",B10)),LEFT(B10,LEN(B10)-3),IF(ISNUMBER(SEARCH("OB",B10)),LEFT(B10,LEN(B10)-3),B10)) | D10: =VLOOKUP($A10,$J:$M,4,FALSE) | E10: =VLOOKUP($A10,$J:$N,5,FALSE) | J10: 7 | K10: Rte 7 Hillsboro IB | L10: 4 | M10: 1 | N10: 68
A11: 19 | B11: =VLOOKUP(A11,$J:$M,2,FALSE) | C11: =IF(ISNUMBER(SEARCH("IB",B11)),LEFT(B11,LEN(B11)-3),IF(ISNUMBER(SEARCH("OB",B11)),LEFT(B11,LEN(B11)-3),B11)) | D11: =VLOOKUP($A11,$J:$M,4,FALSE) | E11: =VLOOKUP($A11,$J:$N,5,FALSE) | J11: 7 | K11: Rte 7 Hillsboro OB | L11: 4 | M11: 1 | N11: 68
A12: 22 | B12: =VLOOKUP(A12,$J:$M,2,FALSE) | C12: =IF(ISNUMBER(SEARCH("IB",B12)),LEFT(B12,LEN(B12)-3),IF(ISNUMBER(SEARCH("OB",B12)),LEFT(B12,LEN(B12)-3),B12)) | D12: =VLOOKUP($A12,$J:$M,4,FALSE) | E12: =VLOOKUP($A12,$J:$N,5,FALSE) | J12: 8 | K12: Rte 8 8TH AVENUE SOUTH iB | L12: 4 | M12: 1 | N12: 73
A13: 23 | B13: =VLOOKUP(A13,$J:$M,2,FALSE) | C13: =IF(ISNUMBER(SEARCH("IB",B13)),LEFT(B13,LEN(B13)-3),IF(ISNUMBER(SEARCH("OB",B13)),LEFT(B13,LEN(B13)-3),B13)) | D13: =VLOOKUP($A13,$J:$M,4,FALSE) | E13: =VLOOKUP($A13,$J:$N,5,FALSE) | J13: 8 | K13: Rte 8 8TH AVENUE SOUTH oB | L13: 4 | M13: 1 | N13: 73
... A45: 112 | B45: =VLOOKUP(A45,$J:$M,2,FALSE) | C45: =IF(ISNUMBER(SEARCH("IB",B45)),LEFT(B45,LEN(B45)-3),IF(ISNUMBER(SEARCH("OB",B45)),LEFT(B45,LEN(B45)-3),B45)) | D45: =VLOOKUP($A45,$J:$M,4,FALSE) | E45: =VLOOKUP($A45,$J:$N,5,FALSE) | J45: 41 | K45: Rte 41 Golden Valley OB AM | L45: 4 | M45: 1 | N45: 58
J46: 42 | K46: Rte 42 St. Cecilia/Cumberland IB | L46: 4 | M46: 1 | N46: 60
J47: 42 | K47: Rte 42 St. Cecilia/Cumberland oB | L47: 4 | M47: 1 | N47: 60
J48: 50 | K48: Rte 50 CHARLOTTE PIKE oB | L48: 4 | M48: 1 | N48: 61
J49: 50 | K49: Rte 50 CHARLOTTE PIKE iB | L49: 4 | M49: 1 | N49: 61
J50: 52 | K50: Rte 52 NOLENSVILLE PIKE (Hick) oB | L50: 4 | M50: 1 | N50: 62
J51: 52 | K51: Rte 52 NOLENSVILLE PIKE (Hick) iB | L51: 4 | M51: 1 | N51: 62
J52: 52 | K52: Rte 52 NOLENSVILLE PIKE (Wall) iB | L52: 4 | M52: 1 | N52: 63
J53: 52 | K53: Rte 52 NOLENSVILLE PIKE (Wall) oB | L53: 4 | M53: 1 | N53: 63
J54: 55 | K54: Rte 55 MURFREESBORO PIKE oB | L54: 4 | M54: 1 | N54: 64
J55: 55 | K55: Rte 55 MURFREESBORO PIKE iB | L55: 4 | M55: 1 | N55: 64
J56: 56 | K56: Rte 56 Gallatin Rd IB | L56: 4 | M56: 1 | N56: 66
J57: 56 | K57: Rte 56 Gallatin Rd oB | L57: 4 | M57: 1 | N57: 66
... J96: 112 | K96: Rte 112 FTA Red Route NS | L96: 4 | M96: 3 | N96: 41
K97: MuleGreenWest | L97: 4 | M97: 2 | N97: 25
K98: MulePurpleEast | L98: 4 | M98: 2 | N98: 26
K99: MuleRedSouth | L99: 4 | M99: 2 | N99: 27
K100: MuleBlueSB | L100: 4 | M100: 2 | N100: 24
K101: Circ_Lebanon_W | L101: 4 | M101: 2 | N101: 18
K102: Circ_Lebanon_E | L102: 4 | M102: 2 | N102: 15
K103: Circ_Lebanon_N | L103: 4 | M103: 2 | N103: 16
K104: Circ_Lebanon_S | L104: 4 | M104: 2 | N104: 17
K105: Circ_MJ_E | L105: 4 | M105: 2 | N105: 19
K106: Circ_MJ_W | L106: 4 | M106: 2 | N106: 22
K107: Circ_MJ_S | L107: 4 | M107: 2 | N107: 21
K108: Circ_MJ_N | L108: 4 | M108: 2 | N108: 20
... K144: BRT_CU1_Corridor iB | L144: 7 | M144: 9 | N144: 3
